Workbook

Sheet FORMULARIO
A3: =IFERROR('Analisis garantia'!BF14,"") -> A | C3: =IFERROR('Analisis garantia'!BF17,"") -> Tasa a Ofrecer | I3: =IFERROR('Analisis de pago'!I6,"") | K3: =IF(I3="","","Calificacion según analisis de pago")
C4: =IFERROR('Analisis garantia'!BF18,"") -> 2.5% - 3.5%
A7: Información General del solicitante
A9: Primer Nombre | F9: Segundo nombre | J9: Edad
A11: Primer apellido | F11: Segundo apellido
A13: Estado Civil | E13: Dirección de residencia
A15: Departamento | G15: Zona | I15: Municipio
A17: Numero de teléfono fijo | G17: Numero de celular
A19: compañía ? | G19: e-mail
A21: Medio en el que nos vio ? | H21: Coinciden direcciones?
H22: *al revisar datos llenar este campo
A24: Información laboral
A26: Ocupación | F26: Empresa
A28: Inicio de labores | F28: Afiliación al IGSS | I28: Numero de afiliación
A30: Ingresos | G30: Egresos
A32: Capacidad de endeudamiento | E32: =B30-H30 -> 0
A34: Dentro de sus egresos paga alguna deuda?
A36: Tiene dependientes económicos? | G36: Cuantos dependientes?
A38: Es usted profesional? | E38: Esta orgulloso de sus actividades
A41: Información crediticia
A43: Tiene cuenta en algún banco ? | G43: Estados de cuenta ?
A45: Tiene o ha tenido tarjeta de crédito? | G45: La tiene al día?
A47: El dinero lo utilizara en ….? | E47: Salud o Medico | H47: Ha tenido algún crédito ?
A49: Cuantos créditos activos tiene? | G49: Monto total que adeuda?
A51: Cuota mensual total? | F51: Capacidad de endeudamiento después de deudas | I51: =E32-D51 -> 0 | K51: =IFERROR(I51/B30,"")
A53: Posee cuotas atrasadas? | F53: Cantidad de cuotas atrasadas?
A55: Monto que requiere ? | F55: Vivienda propia ? | I55: vehículo propio?
A57: Es honrado? | D57: *Responder al revisar en buro crediticio
A59: Información del crédito
A61: Garantía del crédito | D61: Vehículo | G61: Tipo de crédito
A62: Monto requerido
A63: Tasa de interés | F63: =(D63*0.12)+D63 -> 0 | H63: Nivel
A64: Plazo | G64: cuota nivelada ideal | I64: =IFERROR(E32/I63,"")
A65: GPS
A66: Seguro
A67: Cuota nivelada | D67: =IFERROR(IF(A67="Cuota Nivelada",PMT(F63,D64,-D62)+D65+D66,(D62*F63)+D65+D66),0) -> 0 | F67: =IFERROR(D67/H69,"") | H67: Porcentaje que representa la cuota de su capacidad de endeudamiento
A69: Capacidad de endeudamiento después de deudas | H69: =I51 -> 0
A71: Diferencia entre cuota y capacidad de endeudamiento | H71: =H69-D67 -> 0 | I71: =IFERROR(1-F67,"")
A73: ¿La garantía es propia? | E73: Nombre del propietario de la garantía
A75: ¿Toma usted la decisión sobre el crédito ? | H75: ¿Que espera usted de su crédito?
...

Sheet Hoja1
B3: Nombre del propietario | C3: =IF(FORMULARIO!I73="","",FORMULARIO!I73)
B4: Nombre del deudor | C4: =FORMULARIO!C9&Hoja1!C2&FORMULARIO!H9&Hoja1!C2&FORMULARIO!C11&Hoja1!C2&FORMULARIO!H11

Sheet Detalle vehiculo
B1: Detalle de crédito compra de vehiculo
B4: Nombre del Propietario: | C4: AUTOMAQ GUATEMALA, S.A.
B5: Nombre del deudor: | C5: Mario Edú Polanco Fores
B6: Nit del deudor: | D6: 43441726
B7: Garantía | C7: CAMION
B8: Datos: | C8: FOTON CAMION AUMARK E 2026
B9: Inversionista:
A11: ► | B11: MONTO SOLICITADO EN QUETZALES: | I11: =' Cotizador cliente'!C12+' Cotizador cliente'!C18+' Cotizador cliente'!C19 -> 133905.76
G13: % | H13: IVA
B14: Tasa de Interés: | C14: 0.015 | E14: Inversionista | G14: =(I11*C14)*70% -> 1406.0105 | H14: =G14*0.12 -> 168.72126 | I14: =I11*C14*C15 -> 0
A15: ► | B15: MES INTERES ANTICIPADO | C15: 0 | E15: Empresa | G15: =(I11*C14)*30% -> 602.57593 | H15: =G15*0.12 -> 72.309112 | I15: =I14*12/100 -> 0
E16: Inversionista | G16: =G14+H14 -> 1574.7318 | I16: =SUM(I14:I15) -> 0
E17: Empresa | G17: =G15+H15 -> 674.88504
A18: ► | B18: COMISION Y GASTOS DE REGISTRO
D19: Descontado
B20: ROYALTY | D20: SI | G20: 0.04 | H20: =' Cotizador cliente'!D22 -> 5064
B21: Free lance | D21: NO | G21: 0 | H21: =(I11)*G21 -> 0
B22: Free Lance | D22: NO | G22: 0 | H22: =I11*G22 -> 0
B23: Inspección | D23: NO | H23: 0
B24: GPS | D24: NO | H24: 0
B25: Seguro INREXSA | D25: SI | H25: ='Cotizador interno'!C16 -> 805.56
B26: Membresía | D26: SI | H26: ='Cotizador interno'!C19 -> 537.2024
B27: Gastos Administrativos | D27: SI | H27: =' Cotizador cliente'!F22 -> 600
B28: Intereses | D28: SI | H28: =' Cotizador cliente'!G22-H24-H25-H26 -> 2254 | I28: =H20+H21+H27+H24+H25+H26+H28 -> 9260.7624
B30: OTROS DESCUENTOS
B31: Nombramiento | D31: SI | H31: 150
B32: Multas | D32: NO | H32: 0
B33: Copia de llave | D33: NO | H33: 0
B34: Diferencia de copia de llave | D34: NO | H34: 0
B35: Verificación de dirección | D35: SI | H35: 395
B36: Impuesto circulación, 2025 | D36: NO | H36: 0
B37: Traspaso de vehículo | D37: NO | H37: 0
B38: Garantía mobiliaria | D38: SI | H38: =' Cotizador cliente'!E22 -> 400
I39: =SUM(H31:H38) -> 945
B41: GASTOS DE ABOGADO
B42: =IF(B37="Registro de Garantías Mobiliarias","Contrato de Garantía Mobiliaria","Contrato Leasing") -> Contrato Leasing | D42: SI | G42: 1 | H42: 400
B43: Autentica contrato de cobranza | D43: NO
B45: Vehículo comercial
B46: Valor Mercado | C46: 137000
B47: Valor Comercial
...

Sheet Detalle cliente vehiculo
B15: Solicitante: | C15: Mario Edú Polanco Fores
B16: Vehiculo: | C16: FOTON CAMION AUMARK E 2026
B17: Inversionista: | C17: ='Detalle vehiculo'!C9 -> 0
B19: Monto Solicitado | D19: ='Detalle vehiculo'!I11 -> 133905.76
B21: Deducciones
B22: Cuotas interes mensual (interes sobre saldo) | C22: ='Detalle vehiculo'!I16 -> 0
B23: Royalty | C23: ='Detalle vehiculo'!H20 -> 5064
B24: Gastos de Traspaso | C24: ='Detalle vehiculo'!H21+'Detalle vehiculo'!H27+'Detalle vehiculo'!I39 -> 1545
A25: * | B25: Cuotas de seguro (12 cuotas anuales) | C25: 496.53
A26: * | B26: Cuotas de GPS (mensual) | C26: 148.2
B27: Gastos legales | C27: ='Detalle vehiculo'!I48 -> 400 | D27: =SUM(C22:C27) -> 7653.73
B28: Líquido a recibir | D28: =D19-D27 -> 126252.03
B30: *La prima del seguro son 12 cuotas anuales que se pagan mensualmente, al momento de cancelar el credito se cancela el seguro.
B31: *El GPS se paga mensualmente, se cancela al momento de desinstalar el dispositivo GPS.
B33: Nota: El pago de GPS y Seguro son obligatorios y no estan incuidos dentro de la cuota mensual de interes.

Sheet Detalle hipotecario
C4: DETALLE DE GASTOS DE PRÉSTAMO OTORGADO
G11: 43790
B14: Nombre del Propietario: | C14: =FORMULARIO!I73 -> 0
B15: Nombre del Solicitante del crédito: | C15: Mario Oswaldo Rosales Pur
B16: Dirección del Inmueble: | C16: =FORMULARIO!I86 -> 0
B17: Datos del inmueble: | C17: Finca 139, folio 139, libro 2538 de Guatemala
C18: Inversionista:
A20: ► | B20: MONTO SOLICITADO EN QUETZALES: | G20: =C21*E21 -> 300000.01
B21: Tipo de cambio: US$ 1.00 x Q. | C21: 7.7 | E21: 38961.04
E22: % | F22: IVA
B23: Tasa de Interés: | C23: 0.03 | D23: Inversionista | E23: =G20*1.5/100 -> 4500.0001 | F23: =(E23)*12/100 -> 540.00001
A24: ► | B24: MES INTERES ANTICIPADO | C24: 1 | D24: Empresa Club C | E24: =G20*0.5/100 -> 1500 | F24: =(E24)*12/100 -> 180 | G24: =G20*C23*C24 -> 9000.0002
C25: IVA | F25: =(E25)*12/100 -> 0 | G25: =G24*12/100 -> 1080
D26: =D23 -> Inversionista | E26: =E23+F23 -> 5040.0001 | G26: =SUM(G24:G25) -> 10080
D27: =D24 -> Empresa Club C | E27: =SUM(E24:F24) -> 1680
D28: =D25 -> 0 | E28: =(E25)+(F25) -> 0
A29: ► | B29: COMISION Y GASTOS DE REGISTRO
B31: Royalty | E31: 0.04 | F31: =G20*E31 -> 12000 | G31: =SUM(F31:F36) -> 16591.25
B32: Otros Gastos | E32: 0.01 | F32: =G20*E32 -> 3000.0001
B33: IUSI | F33: 0
B34: Gastos administrativos | F34: 600
B35: Seguro | F35: 0
B36: Gastos de Registro (Registro Propiedad Inmueble) | F36: ='Cálculo RGPI'!C26 -> 991.25
B37: Otros Gastos
B39: GASTOS ESCRITURACION Y REGISTRO
B40: Memorial para registro temporal e inscripción RGPI | F40: 0
B41: Otros descuentos | F41: 0
G42: =SUM(F40:F41) -> 0
A44: ► | B44: GASTOS DE ABOGADO | G44: =SUM(F45:F50) -> 4060.0001
B45: Honorarios Escrituración | E45: 0.01 | F45: =(G20)*(E45)+(100) -> 3100.0001
B46: IVA | E46: =G16*0.3/100 -> 0 | F46: =(G20)*1/100*12/100 -> 360.00001
B47: Impuesto (base x millar) | C47: 2 | D47: o/oo | E47: 0 | F47: =G20*0.2/100 -> 600.00002
B48: Contrato de cobro | E48: 0 | F48: 0
B49: Liberación del inmueble | E49: 0 | F49: 0
B50: Carta de Pago | E50: 0 | F50: 0
B51: CALCULOS PAGO IMPUESTO DE OPERACIÓN
D52: x | E52: 0
D53: x | E53: 0
B54: Pago de Timbres
B55: Pago a efectuar de Hipoteca a nombre de:
...

Sheet Detalle cliente hipotecario
E11: 43790
A13: Solicitante:
A14: Mario Oswaldo Rosales Pur
A16: Préstamo otorgado | C16: ='Detalle hipotecario'!G20 -> 300000.01
A18: Deducciones
A19: 3% mensual 1a.cuota (incluye IVA) | B19: ='Detalle hipotecario'!G26 -> 10080
A20: Royalty 4% | B20: ='Detalle hipotecario'!F31 -> 12000
A21: Gastos Administrativos | B21: ='Detalle hipotecario'!F32+'Detalle hipotecario'!F34 -> 3600.0001
A22: Inscripciones (1o. Y 2do. Lugar, RGPI) | B22: ='Detalle hipotecario'!F36 -> 991.25
A23: Honorarios abogado | B23: ='Detalle hipotecario'!G44 -> 4060.0001 | C23: =SUM(B19:B23) -> 30731.251
A24: Líquido a recibir | C24: =C16-C23 -> 269268.76

Sheet Cálculo RGPI
A3: Base de cálculo Gastos de Registro
A4: 250000 | B4: - Q 10,0000 | C4: =A4-10000 -> 240000 | D4: =+A4/7.89 -> 31685.678
A6: =C4 -> 240000 | B6: x .015% | C6: =+A6*0.15/100 -> 360
A7: (+) Gastos
A8: Inscripción Registro | C8: =160+50 -> 210
A9: Scanner documento | C9: 75
A10: Gastos extraordinarios | C10: 0
C11: =+C10+C9+C8+C6 -> 645
A15: Base de cálculo Gastos de Registro
A16: 50000 | B16: - Q 10,0000 | C16: =A16-10000 -> 40000 | D16: =+A16/7.89 -> 6337.1356
A18: =C16 -> 40000 | B18: x .015% | C18: =+A18*0.15/100 -> 60
A19: (+) Gastos
A20: Inscripción Registro | C20: =160+50 -> 210
A21: Scanner documento | C21: 75
A22: Gastos extraordinarios | C22: 0
C23: =+C22+C21+C20+C18 -> 345
C26: =+C23+C11+(1.25) -> 991.25

Sheet Emision de Cheques
J8: MONEDA | K8: MONTO
A9: FECHA | B9: EMISOR | C9: BANCO | D9: BENEFICIARIO | E9: NO.CUENTA | F9: TIPO | G9: TIPO DE CUENTA | H9: BANCO | I9: CONCEPTO | J9: Q | K9: Q
A10: 45996 | B10: Cube Investments, S.A. | C10: BAM | D10: AUTOMAQ GUATEMALA, S.A. (No Negociable) | E10: 30-2009653-9 | F10: TRASFERENCIA | G10: MONETARIA | H10: BAM | I10: Credito otorgado a Mario Edú Polanco Fores | J10: X | K10: =IF(FORMULARIO!D61="Hipotecario",'Detalle hipotecario'!F58,'Detalle vehiculo'!I52) -> 123300
A11: 45996 | B11: Cube Investments, S.A. | C11: BAM | D11: Cube Investments, S.A. (No Negociable) | F11: TRASFERENCIA | G11: MONETARIA | H11: BAM | I11: Gastos Administrativos, contratos, garantía, visita domiciliar | J11: X | K11: ='Detalle vehiculo'!I50 -> 10605.762
K12: 0
K13: =SUM(K10:K12) -> 133905.76
A19: © CLUB CASH IN . Este documento es propiedad de Club Cash In, copia u otro uso de este documento por y para terceras personas está prohibida.

Sheet  Cotizador cliente
A1: Detalle de cuotas niveladas
A3: Datos del vehículo
B5: Marca: | C5: FOTON | D5: Línea: | E5: AUMARK E | F5: Modelo: | G5: 2026
A7: Nombre: | B7: Mario Edú Polanco Fores | F7: Camion
A9: Valor del vehículo: | C9: 137000
A10: Monto asegurado: | C10: 137000
A11: Enganche: | C11: 13700 | D11: =C11/C9 -> 0.1
A12: Monto a financiar: | C12: =C9-C11 -> 123300 | D12: =(C12/C9) -> 0.9
A14: Plazo (meses): | C14: 60
A15: Tasa de interés: | C15: 0.015
A16: Seguro: | C16: =IF(F7="UBER",VLOOKUP(C10,'Costo seguro'!B2:G782,2,TRUE),IF(F7="Particular",VLOOKUP(C10,'Costo seguro'!B2:G782,2,TRUE),IF(F7="Pick Up",VLOOKUP(C10,'Costo seguro'!B2:G782,3,TRUE),IF(F7="Nuevo",VLOOKUP(C10,'Costo seguro'!B2:G782,2,TRUE),IF(F7="Panel",VLOOKUP(C10,'Costo seguro'!B2:G782,4,TRUE),IF(F7="Camion",VLOOKUP(C10,'Costo seguro'!B2:G782,4,TRUE),IF(F7="Microbus",VLOOKUP(C10,'Costo seguro'!B2:G782,4,TRUE),"")))))))+C20 -> 1194.5624
A17: GPS | C17: 148.2 | E17: Monto total a financiar:
A18: Traspaso | C18: =395+150 -> 545
A19: Gastos administrativos | C19: =C22+D22+E22+F22+G22 -> 10060.762 | E19: Cuota mensual: | F19: =PMT((C15*1.12),C14,-(C12+C18+C19))+C16+C17 -> 4902.3778
A20: Membresía | C20: =VLOOKUP(C10,'Costo seguro'!B2:K782,5,TRUE)-C17 -> 389.0024
B22: =C12+C18+C22+E22+F22+C17+C16 -> 126587.76 | C22: 400 | D22: =ROUNDUP(B22*4%,0) -> 5064 | E22: 400 | F22: 600 | G22: =ROUNDUP(B22*1.78%,0)+C17+C16 -> 3596.7624
B23: Cuota | C23: Saldo inicial | D23: Interés + IVA | E23: Amortización | F23: Saldo final
B24: 0 | C24: =C12+C18+C19 -> 133905.76 | D24: =((C24)*C15*1.12) -> 2249.6168 | E24: 0 | F24: =C24-E24 -> 133905.76
B25: =IF(C25="","",B24+1) -> 1 | C25: =IF(F24<=0.1,"",IF(C24="","",F24)) -> 133905.76 | D25: =IF(C25="","",(C25*$C$15*1.12)) -> 2249.6168 | E25: =IF(D25="","",$F$19-$C$16-$C$17-D25) -> 1309.9986 | F25: =IF(E25="","",C25-E25) -> 132595.76
B26: =IF(C26="","",B25+1) -> 2 | C26: =IF(F25<=0.1,"",IF(C25="","",F25)) -> 132595.76 | D26: =IF(C26="","",(C26*$C$15*1.12)) -> 2227.6088 | E26: =IF(D26="","",$F$19-$C$16-$C$17-D26) -> 1332.0065 | F26: =IF(E26="","",C26-E26) -> 131263.76
B27: =IF(C27="","",B26+1) -> 3 | C27: =IF(F26<=0.1,"",IF(C26="","",F26)) -> 131263.76 | D27: =IF(C27="","",(C27*$C$15*1.12)) -> 2205.2311 | E27: =IF(D27="","",$F$19-$C$16-$C$17-D27) -> 1354.3843 | F27: =IF(E27="","",C27-E27) -> 129909.37
B28: =IF(C28="","",B27+1) -> 4 | C28: =IF(F27<=0.1,"",IF(C27="","",F27)) -> 129909.37 | D28: =IF(C28="","",(C28*$C$15*1.12)) -> 2182.4775 | E28: =IF(D28="","",$F$19-$C$16-$C$17-D28) -> 1377.1379 | F28: =IF(E28="","",C28-E28) -> 128532.24
B29: =IF(C29="","",B28+1) -> 5 | C29: =IF(F28<=0.1,"",IF(C28="","",F28)) -> 128532.24 | D29: =IF(C29="","",(C29*$C$15*1.12)) -> 2159.3415 | E29: =IF(D29="","",$F$19-$C$16-$C$17-D29) -> 1400.2738 | F29: =IF(E29="","",C29-E29) -> 127131.96
B30: =IF(C30="","",B29+1) -> 6 | C30: =IF(F29<=0.1,"",IF(C29="","",F29)) -> 127131.96 | D30: =IF(C30="","",(C30*$C$15*1.12)) -> 2135.8169 | E30: =IF(D30="","",$F$19-$C$16-$C$17-D30) -> 1423.7984 | F30: =IF(E30="","",C30-E30) -> 125708.16
B31: =IF(C31="","",B30+1) -> 7 | C31: =IF(F30<=0.1,"",IF(C30="","",F30)) -> 125708.16 | D31: =IF(C31="","",(C31*$C$15*1.12)) -> 2111.8971 | E31: =IF(D31="","",$F$19-$C$16-$C$17-D31) -> 1447.7182 | F31: =IF(E31="","",C31-E31) -> 124260.44
B32: =IF(C32="","",B31+1) -> 8 | C32: =IF(F31<=0.1,"",IF(C31="","",F31)) -> 124260.44 | D32: =IF(C32="","",(C32*$C$15*1.12)) -> 2087.5755 | E32: =IF(D32="","",$F$19-$C$16-$C$17-D32) -> 1472.0399 | F32: =IF(E32="","",C32-E32) -> 122788.4
B33: =IF(C33="","",B32+1) -> 9 | C33: =IF(F32<=0.1,"",IF(C32="","",F32)) -> 122788.4 | D33: =IF(C33="","",(C33*$C$15*1.12)) -> 2062.8452 | E33: =IF(D33="","",$F$19-$C$16-$C$17-D33) -> 1496.7702 | F33: =IF(E33="","",C33-E33) -> 121291.63
B34: =IF(C34="","",B33+1) -> 10 | C34: =IF(F33<=0.1,"",IF(C33="","",F33)) -> 121291.63 | D34: =IF(C34="","",(C34*$C$15*1.12)) -> 2037.6995 | E34: =IF(D34="","",$F$19-$C$16-$C$17-D34) -> 1521.9159 | F34: =IF(E34="","",C34-E34) -> 119769.72
B35: =IF(C35="","",B34+1) -> 11 | C35: =IF(F34<=0.1,"",IF(C34="","",F34)) -> 119769.72 | D35: =IF(C35="","",(C35*$C$15*1.12)) -> 2012.1313 | E35: =IF(D35="","",$F$19-$C$16-$C$17-D35) -> 1547.4841 | F35: =IF(E35="","",C35-E35) -> 118222.23
B36: =IF(C36="","",B35+1) -> 12 | C36: =IF(F35<=0.1,"",IF(C35="","",F35)) -> 118222.23 | D36: =IF(C36="","",(C36*$C$15*1.12)) -> 1986.1335 | E36: =IF(D36="","",$F$19-$C$16-$C$17-D36) -> 1573.4818 | F36: =IF(E36="","",C36-E36) -> 116648.75
... B135: =IF(C135="","",B134+1) | C135: =IF(F134<=0.1,"",IF(C134="","",F134)) | D135: =IF(C135="","",(C135*$C$15*1.12)) | E135: =IF(D135="","",$F$19-$C$16-$C$17-D135) | F135: =IF(E135="","",C135-E135)

Sheet Cotizador interno
A1: Detalle de cuotas niveladas
A3: Datos del vehículo
B5: Marca: | C5: =' Cotizador cliente'!C5 -> FOTON | D5: Línea: | E5: =' Cotizador cliente'!E5 -> AUMARK E | F5: Modelo: | G5: =' Cotizador cliente'!G5 -> 2026
A7: Nombre: | B7: =' Cotizador cliente'!B7:E7 -> Mario Edú Polanco Fores | G7: =' Cotizador cliente'!F7 -> Camion
A9: Valor del vehículo: | C9: =' Cotizador cliente'!C9 -> 137000
A10: Monto asegurado: | C10: =' Cotizador cliente'!C10 -> 137000
A11: Enganche: | C11: =' Cotizador cliente'!C11 -> 13700 | D11: =C11/C9 -> 0.1
A12: Monto a financiar: | C12: =' Cotizador cliente'!C12 -> 123300 | D12: =(C12/C9) -> 0.9
A14: Plazo (meses): | C14: =' Cotizador cliente'!C14 -> 60
A15: Tasa de interés: | C15: =' Cotizador cliente'!C15 -> 0.015
A16: Seguro: | C16: =IF(G7="UBER",VLOOKUP(C10,'Costo seguro'!B2:G782,2,TRUE),IF(G7="Particular",VLOOKUP(C10,'Costo seguro'!B2:G782,2,TRUE),IF(G7="Pick Up",VLOOKUP(C10,'Costo seguro'!B2:G782,3,TRUE),IF(G7="Nuevo",VLOOKUP(C10,'Costo seguro'!B2:G782,2,TRUE),IF(G7="Panel",VLOOKUP(C10,'Costo seguro'!B2:G782,4,TRUE),IF(G7="Camion",VLOOKUP(C10,'Costo seguro'!B2:G782,4,TRUE),IF(G7="Microbus",VLOOKUP(C10,'Costo seguro'!B2:G782,4,TRUE),""))))))) -> 805.56 | E16: Monto total a financiar:
A17: Traspaso | C17: =' Cotizador cliente'!C18 -> 545
A18: Gastos administrativos | C18: =' Cotizador cliente'!C19 -> 10060.762 | E18: Cuota mensual: | F18: =PMT((C15*1.12),C14,-(C12+C17+C18))+C16+C19 -> 4902.3778
A19: Membresía | C19: =VLOOKUP(C10,'Costo seguro'!B2:K782,5,TRUE) -> 537.2024
B21: Cuota | C21: Saldo inicial | D21: Interés + IVA | E21: Amortización | F21: Saldo final
B22: 1 | C22: =' Cotizador cliente'!C24 -> 133905.76 | D22: =((C22)*C15*1.12) -> 2249.6168 | E22: =$F$18-$C$16-D22-C19 -> 1309.9986 | F22: =C22-E22 -> 132595.76
B23: =IF(C23="","",B22+1) -> 2 | C23: =IF(F22<=0.1,"",IF(C22="","",F22)) -> 132595.76 | D23: =IF(C23="","",(C23*$C$15*1.12)) -> 2227.6088 | E23: =IF(D23="","",$F$18-$C$16-D23-$C$19) -> 1332.0065 | F23: =IF(E23="","",C23-E23) -> 131263.76
B24: =IF(C24="","",B23+1) -> 3 | C24: =IF(F23<=0.1,"",IF(C23="","",F23)) -> 131263.76 | D24: =IF(C24="","",(C24*$C$15*1.12)) -> 2205.2311 | E24: =IF(D24="","",$F$18-$C$16-D24-$C$19) -> 1354.3843 | F24: =IF(E24="","",C24-E24) -> 129909.37
B25: =IF(C25="","",B24+1) -> 4 | C25: =IF(F24<=0.1,"",IF(C24="","",F24)) -> 129909.37 | D25: =IF(C25="","",(C25*$C$15*1.12)) -> 2182.4775 | E25: =IF(D25="","",$F$18-$C$16-D25-$C$19) -> 1377.1379 | F25: =IF(E25="","",C25-E25) -> 128532.24
B26: =IF(C26="","",B25+1) -> 5 | C26: =IF(F25<=0.1,"",IF(C25="","",F25)) -> 128532.24 | D26: =IF(C26="","",(C26*$C$15*1.12)) -> 2159.3415 | E26: =IF(D26="","",$F$18-$C$16-D26-$C$19) -> 1400.2738 | F26: =IF(E26="","",C26-E26) -> 127131.96
B27: =IF(C27="","",B26+1) -> 6 | C27: =IF(F26<=0.1,"",IF(C26="","",F26)) -> 127131.96 | D27: =IF(C27="","",(C27*$C$15*1.12)) -> 2135.8169 | E27: =IF(D27="","",$F$18-$C$16-D27-$C$19) -> 1423.7984 | F27: =IF(E27="","",C27-E27) -> 125708.16
B28: =IF(C28="","",B27+1) -> 7 | C28: =IF(F27<=0.1,"",IF(C27="","",F27)) -> 125708.16 | D28: =IF(C28="","",(C28*$C$15*1.12)) -> 2111.8971 | E28: =IF(D28="","",$F$18-$C$16-D28-$C$19) -> 1447.7182 | F28: =IF(E28="","",C28-E28) -> 124260.44
B29: =IF(C29="","",B28+1) -> 8 | C29: =IF(F28<=0.1,"",IF(C28="","",F28)) -> 124260.44 | D29: =IF(C29="","",(C29*$C$15*1.12)) -> 2087.5755 | E29: =IF(D29="","",$F$18-$C$16-D29-$C$19) -> 1472.0399 | F29: =IF(E29="","",C29-E29) -> 122788.4
B30: =IF(C30="","",B29+1) -> 9 | C30: =IF(F29<=0.1,"",IF(C29="","",F29)) -> 122788.4 | D30: =IF(C30="","",(C30*$C$15*1.12)) -> 2062.8452 | E30: =IF(D30="","",$F$18-$C$16-D30-$C$19) -> 1496.7702 | F30: =IF(E30="","",C30-E30) -> 121291.63
B31: =IF(C31="","",B30+1) -> 10 | C31: =IF(F30<=0.1,"",IF(C30="","",F30)) -> 121291.63 | D31: =IF(C31="","",(C31*$C$15*1.12)) -> 2037.6995 | E31: =IF(D31="","",$F$18-$C$16-D31-$C$19) -> 1521.9159 | F31: =IF(E31="","",C31-E31) -> 119769.72
B32: =IF(C32="","",B31+1) -> 11 | C32: =IF(F31<=0.1,"",IF(C31="","",F31)) -> 119769.72 | D32: =IF(C32="","",(C32*$C$15*1.12)) -> 2012.1313 | E32: =IF(D32="","",$F$18-$C$16-D32-$C$19) -> 1547.4841 | F32: =IF(E32="","",C32-E32) -> 118222.23
B33: =IF(C33="","",B32+1) -> 12 | C33: =IF(F32<=0.1,"",IF(C32="","",F32)) -> 118222.23 | D33: =IF(C33="","",(C33*$C$15*1.12)) -> 1986.1335 | E33: =IF(D33="","",$F$18-$C$16-D33-$C$19) -> 1573.4818 | F33: =IF(E33="","",C33-E33) -> 116648.75
B34: =IF(C34="","",B33+1) -> 13 | C34: =IF(F33<=0.1,"",IF(C33="","",F33)) -> 116648.75 | D34: =IF(C34="","",(C34*$C$15*1.12)) -> 1959.699 | E34: =IF(D34="","",$F$18-$C$16-D34-$C$19) -> 1599.9163 | F34: =IF(E34="","",C34-E34) -> 115048.84
... B133: =IF(C133="","",B132+1) | C133: =IF(F132<=0.1,"",IF(C132="","",F132)) | D133: =IF(C133="","",(C133*$C$15*1.12)) | E133: =IF(D133="","",$F$18-$C$16-D133-$C$19) | F133: =IF(E133="","",C133-E133)
E134: =IF(D134="","",$F$18-$C$16-D134-$C$19)
E135: =IF(D135="","",$F$18-$C$16-D135-$C$19)

Sheet Costo seguro
B1: Precio | C1: INREXSA | D1: Pick Up | E1: Panel, Camion, Microbus | F1: Membresia | I1: INREXSA | J1: Pick Up | K1: Panel, Camion, Microbus | L1: Membresia
B2: 20000 | C2: 245 | D2: 245 | E2: 245 | F2: 329.365 | I2: 260.925 | J2: 260.925 | K2: 260.925 | L2: 313.44
B3: 21000 | C3: 245 | D3: 245 | E3: 245 | F3: 329.365 | I3: 260.925 | J3: 260.925 | K3: 260.925 | L3: 313.44
B4: 22000 | C4: 245 | D4: 245 | E4: 245 | F4: 329.365 | I4: 260.925 | J4: 260.925 | K4: 260.925 | L4: 313.44
B5: 23000 | C5: 245 | D5: 245 | E5: 245 | F5: 329.365 | I5: 260.925 | J5: 260.925 | K5: 260.925 | L5: 313.44
B6: 24000 | C6: 245 | D6: 245 | E6: 245 | F6: 329.365 | I6: 260.925 | J6: 260.925 | K6: 260.925 | L6: 313.44
B7: 25000 | C7: 245 | D7: 245 | E7: 245 | F7: 329.365 | I7: 260.925 | J7: 260.925 | K7: 260.925 | L7: 313.44
B8: 26000 | C8: 245 | D8: 245 | E8: 245 | F8: 329.365 | I8: 260.925 | J8: 260.925 | K8: 260.925 | L8: 313.44
B9: 27000 | C9: 245 | D9: 245 | E9: 245 | F9: 329.365 | I9: 260.925 | J9: 260.925 | K9: 260.925 | L9: 313.44
B10: 28000 | C10: 245 | D10: 245 | E10: 245 | F10: 329.365 | I10: 260.925 | J10: 260.925 | K10: 260.925 | L10: 313.44
B11: 29000 | C11: 245 | D11: 245 | E11: 245 | F11: 329.365 | I11: 260.925 | J11: 260.925 | K11: 260.925 | L11: 313.44
B12: 30000 | C12: 245 | D12: 245 | E12: 245 | F12: 329.365 | I12: 260.925 | J12: 260.925 | K12: 260.925 | L12: 313.44
B13: 31000 | C13: 245 | D13: 245 | E13: 245 | F13: 329.365 | I13: 260.925 | J13: 260.925 | K13: 260.925 | L13: 313.44
... B782: 800000 | C782: 2156 | D782: 2399.04 | E782: 4704 | F782: 2339.7931 | I782: 2296.14 | J782: 2554.9776 | K782: 5009.76 | L782: 2034.0331

Sheet Costo seguro (2)
B1: Precio | C1: Precio antiguo | D1: Precio nuevo | E1: UBER | F1: Nuevo - Viejo | G1: Nuevo - Nuevo | H1: Bus hasta 20 pasajeros | I1: Bus 21-35 pasajeros | J1: Bus mas de 35 pasajeros | K1: Membresia parcial usados | L1: Membresia total usados | M1: Membresia parcial nuevos | N1: Membresia total nuevos | O1: Membresía | P1: 0.15
B2: 1 | C2: 276.43 | D2: 225.4 | E2: =C2 -> 276.43 | F2: 362.99 | G2: 300.96 | H2: 486.64 | I2: 561.64 | J2: 711.64 | K2: =L2-(C2-D2)-10.2 -> 133.81 | L2: =(D2*$P$1)+(C2-D2)+10.2+100 -> 195.04 | M2: =N2-(F2-G2)-10.2 -> 122.81 | N2: =L2 -> 195.04
B3: 1000 | C3: 276.43 | D3: 225.4 | E3: =C3 -> 276.43 | F3: 362.99 | G3: 300.96 | H3: 486.64 | I3: 561.64 | J3: 711.64 | K3: =L3-(C3-D3)-10.2 -> 133.81 | L3: =(D3*$P$1)+(C3-D3)+10.2+100 -> 195.04 | M3: =N3-(F3-G3)-10.2 -> 122.81 | N3: =L3 -> 195.04
B4: 5000 | C4: 276.43 | D4: 225.4 | E4: =C4 -> 276.43 | F4: 362.99 | G4: 300.96 | H4: 486.64 | I4: 561.64 | J4: 711.64 | K4: =L4-(C4-D4)-10.2 -> 133.81 | L4: =(D4*$P$1)+(C4-D4)+10.2+100 -> 195.04 | M4: =N4-(F4-G4)-10.2 -> 122.81 | N4: =L4 -> 195.04
B5: 10000 | C5: 276.43 | D5: 225.4 | E5: =C5 -> 276.43 | F5: 362.99 | G5: 300.96 | H5: 486.64 | I5: 561.64 | J5: 711.64 | K5: =L5-(C5-D5)-10.2 -> 133.81 | L5: =(D5*$P$1)+(C5-D5)+10.2+100 -> 195.04 | M5: =N5-(F5-G5)-10.2 -> 122.81 | N5: =L5 -> 195.04
B6: 15000 | C6: 276.43 | D6: 225.4 | E6: =C6 -> 276.43 | F6: 362.99 | G6: 300.96 | H6: 486.64 | I6: 561.64 | J6: 711.64 | K6: =L6-(C6-D6)-10.2 -> 133.81 | L6: =(D6*$P$1)+(C6-D6)+10.2+100 -> 195.04 | M6: =N6-(F6-G6)-10.2 -> 122.81 | N6: =L6 -> 195.04
B7: 20000 | C7: 276.43 | D7: 225.4 | E7: =C7 -> 276.43 | F7: 362.99 | G7: 300.96 | H7: 486.64 | I7: 561.64 | J7: 711.64 | K7: =L7-(C7-D7)-10.2 -> 133.81 | L7: =(D7*$P$1)+(C7-D7)+10.2+100 -> 195.04 | M7: =N7-(F7-G7)-10.2 -> 122.81 | N7: =L7 -> 195.04
B8: 25000 | C8: 276.43 | D8: 225.4 | E8: =C8 -> 276.43 | F8: 362.99 | G8: 300.96 | H8: 486.64 | I8: 561.64 | J8: 711.64 | K8: =L8-(C8-D8)-10.2 -> 133.81 | L8: =(D8*$P$1)+(C8-D8)+10.2+100 -> 195.04 | M8: =N8-(F8-G8)-10.2 -> 122.81 | N8: =L8 -> 195.04
B9: 30000 | C9: 276.43 | D9: 225.4 | E9: =C9 -> 276.43 | F9: 362.99 | G9: 300.96 | H9: 486.64 | I9: 561.64 | J9: 711.64 | K9: =L9-(C9-D9)-10.2 -> 133.81 | L9: =(D9*$P$1)+(C9-D9)+10.2+100 -> 195.04 | M9: =N9-(F9-G9)-10.2 -> 122.81 | N9: =L9 -> 195.04
B10: 35000 | C10: 276.43 | D10: 225.4 | E10: =C10 -> 276.43 | F10: 362.99 | G10: 300.96 | H10: 486.64 | I10: 561.64 | J10: 711.64 | K10: =L10-(C10-D10)-10.2 -> 133.81 | L10: =(D10*$P$1)+(C10-D10)+10.2+100 -> 195.04 | M10: =N10-(F10-G10)-10.2 -> 122.81 | N10: =L10 -> 195.04
B11: 40000 | C11: 302.75 | D11: 225.4 | E11: =C11 -> 302.75 | F11: 362.99 | G11: 300.96 | H11: 486.64 | I11: 561.64 | J11: 711.64 | K11: =L11-(C11-D11)-10.2 -> 151.64 | L11: =139.19+100 -> 239.19 | M11: =N11-(F11-G11)-10.2 -> 166.96 | N11: =L11 -> 239.19
B12: 45000 | C12: 320.55 | D12: 225.4 | E12: =C12 -> 320.55 | F12: 362.99 | G12: 300.96 | H12: 510.16 | I12: 585.16 | J12: 735.16 | K12: =L12-(C12-D12)-10.2 -> 133.84 | L12: =139.19+100 -> 239.19 | M12: =N12-(F12-G12)-10.2 -> 166.96 | N12: =L12 -> 239.19
B13: 50000 | C13: 338.35 | D13: 267.54 | E13: =C13 -> 338.35 | F13: 362.99 | G13: 300.96 | H13: 533.68 | I13: 608.68 | J13: 758.68 | K13: =L13-(C13-D13)-10.2 -> 158.18 | L13: =139.19+100 -> 239.19 | M13: =N13-(F13-G13)-10.2 -> 166.96 | N13: =L13 -> 239.19
B14: 55000 | C14: 356.15 | D14: 281.06 | E14: =C14 -> 356.15 | F14: 362.99 | G14: 300.96 | H14: 557.2 | I14: 632.2 | J14: 782.2 | K14: =L14-(C14-D14)-10.2 -> 153.9 | L14: =139.19+100 -> 239.19 | M14: =N14-(F14-G14)-10.2 -> 166.96 | N14: =L14 -> 239.19
B15: 60000 | C15: 373.95 | D15: 302.56 | E15: =C15 -> 373.95 | F15: 362.99 | G15: 300.96 | H15: 580.72 | I15: 655.72 | J15: 805.72 | K15: =L15-(C15-D15)-10.2 -> 157.6 | L15: =139.19+100 -> 239.19 | M15: =N15-(F15-G15)-10.2 -> 166.96 | N15: =L15 -> 239.19
B16: 65000 | C16: 391.76 | D16: 316.45 | E16: =C16 -> 391.76 | F16: 362.99 | G16: 300.96 | H16: 604.24 | I16: 679.24 | J16: 829.24 | K16: =L16-(C16-D16)-10.2 -> 153.68 | L16: =139.19+100 -> 239.19 | M16: =N16-(F16-G16)-10.2 -> 166.96 | N16: =L16 -> 239.19
B17: 70000 | C17: 409.56 | D17: 362.9 | E17: =C17 -> 409.56 | F17: 362.99 | G17: 300.96 | H17: 627.76 | I17: 702.76 | J17: 852.76 | K17: =L17-(C17-D17)-10.2 -> 182.33 | L17: =139.19+100 -> 239.19 | M17: =N17-(F17-G17)-10.2 -> 166.96 | N17: =L17 -> 239.19
B18: 75000 | C18: 427.36 | D18: 378.16 | E18: =C18 -> 427.36 | F18: 378.77 | G18: 313.36 | H18: 651.28 | I18: 726.28 | J18: 876.28 | K18: =L18-(C18-D18)-10.2 -> 179.79 | L18: =139.19+100 -> 239.19 | M18: =N18-(F18-G18)-10.2 -> 163.58 | N18: =L18 -> 239.19
B19: 80000 | C19: 445.16 | D19: 393.42 | E19: =C19 -> 445.16 | F19: 394.55 | G19: 325.75 | H19: 674.8 | I19: 749.8 | J19: 899.8 | K19: =L19-(C19-D19)-10.2 -> 177.25 | L19: =139.19+100 -> 239.19 | M19: =N19-(F19-G19)-10.2 -> 160.19 | N19: =L19 -> 239.19
B20: 85000 | C20: 462.96 | D20: 408.67 | E20: =C20 -> 462.96 | F20: 462.96 | G20: 381.53 | H20: 698.32 | I20: 773.32 | J20: 923.32 | K20: =L20-(C20-D20)-10.2 -> 174.7 | L20: =139.19+100 -> 239.19 | M20: =N20-(F20-G20)-10.2 -> 147.56 | N20: =L20 -> 239.19
B21: 90000 | C21: 480.77 | D21: 423.93 | E21: =C21 -> 480.77 | F21: 480.77 | G21: 395.52 | H21: 721.84 | I21: 796.84 | J21: 946.84 | K21: =L21-(C21-D21)-10.2 -> 172.15 | L21: =139.19+100 -> 239.19 | M21: =N21-(F21-G21)-10.2 -> 143.74 | N21: =L21 -> 239.19
B22: 95000 | C22: 498.57 | D22: 439.19 | E22: =C22 -> 498.57 | F22: 498.57 | G22: 409.5 | H22: 745.36 | I22: 820.36 | J22: 970.36 | K22: =L22-(C22-D22)-10.2 -> 169.61 | L22: =139.19+100 -> 239.19 | M22: =N22-(F22-G22)-10.2 -> 139.92 | N22: =L22 -> 239.19
B23: 100000 | C23: 516.37 | D23: 387 | E23: =C23 -> 516.37 | F23: 387 | G23: 359.36 | H23: 768.88 | I23: 843.88 | J23: 993.88 | K23: =L23-(C23-D23)-10.2 -> 158.05 | L23: 297.62 | M23: =N23-(F23-G23)-10.2 -> 259.78 | N23: =L23 -> 297.62
B24: 105000 | C24: 485.41 | D24: 399.16 | E24: =C24 -> 485.41 | F24: 399.16 | G24: 370.42 | H24: 792.4 | I24: 867.4 | J24: 1017.4 | K24: =L24-(C24-D24)-10.2 -> 201.17 | L24: 297.62 | M24: =N24-(F24-G24)-10.2 -> 258.68 | N24: =L24 -> 297.62
B25: 110000 | C25: 500.89 | D25: 411.33 | E25: =C25 -> 500.89 | F25: 411.33 | G25: 381.47 | H25: 815.92 | I25: 890.92 | J25: 1040.92 | K25: =L25-(C25-D25)-10.2 -> 197.86 | L25: 297.62 | M25: =N25-(F25-G25)-10.2 -> 257.56 | N25: =L25 -> 297.62
B26: 115000 | C26: 516.37 | D26: 423.49 | E26: =C26 -> 516.37 | F26: 423.49 | G26: 392.53 | H26: 839.44 | I26: 914.44 | J26: 1064.44 | K26: =L26-(C26-D26)-10.2 -> 194.54 | L26: 297.62 | M26: =N26-(F26-G26)-10.2 -> 256.46 | N26: =L26 -> 297.62
B27: 120000 | C27: 531.85 | D27: 435.65 | E27: =C27 -> 531.85 | F27: 435.65 | G27: 403.59 | H27: 862.96 | I27: 937.96 | J27: 1087.96 | K27: =L27-(C27-D27)-10.2 -> 191.22 | L27: 297.62 | M27: =N27-(F27-G27)-10.2 -> 255.36 | N27: =L27 -> 297.62
B28: 125000 | C28: 547.33 | D28: 447.82 | E28: =C28 -> 547.33 | F28: 447.82 | G28: 414.65 | H28: 886.48 | I28: 961.48 | J28: 1111.48 | K28: =L28-(C28-D28)-10.2 -> 187.91 | L28: 297.62 | M28: =N28-(F28-G28)-10.2 -> 254.25 | N28: =L28 -> 297.62
B29: 130000 | C29: 562.81 | D29: 459.98 | E29: =C29 -> 562.81 | F29: 459.98 | G29: 425.7 | H29: 910 | I29: 985 | J29: 1135 | K29: =L29-(C29-D29)-10.2 -> 184.59 | L29: 297.62 | M29: =N29-(F29-G29)-10.2 -> 253.14 | N29: =L29 -> 297.62
B30: 135000 | C30: 578.29 | D30: 472.14 | E30: =C30 -> 578.29 | F30: 472.14 | G30: 436.76 | H30: 933.52 | I30: 1008.52 | J30: 1158.52 | K30: =L30-(C30-D30)-10.2 -> 181.27 | L30: 297.62 | M30: =N30-(F30-G30)-10.2 -> 252.04 | N30: =L30 -> 297.62
B31: 140000 | C31: 593.77 | D31: 484.31 | E31: =C31 -> 593.77 | F31: 484.31 | G31: 447.82 | H31: 957.04 | I31: 1032.04 | J31: 1182.04 | K31: =L31-(C31-D31)-10.2 -> 177.96 | L31: 297.62 | M31: =N31-(F31-G31)-10.2 -> 250.93 | N31: =L31 -> 297.62
B32: 145000 | C32: 571.66 | D32: 496.47 | E32: =C32 -> 571.66 | F32: 496.47 | G32: 458.87 | H32: 980.56 | I32: 1055.56 | J32: 1205.56 | K32: =L32-(C32-D32)-10.2 -> 212.23 | L32: 297.62 | M32: =N32-(F32-G32)-10.2 -> 249.82 | N32: =L32 -> 297.62
B33: 150000 | C33: 586.03 | D33: 508.63 | E33: =C33 -> 586.03 | F33: 508.63 | G33: 469.93 | H33: 1004.08 | I33: 1079.08 | J33: 1229.08 | K33: =L33-(C33-D33)-10.2 -> 210.02 | L33: 297.62 | M33: =N33-(F33-G33)-10.2 -> 248.72 | N33: =L33 -> 297.62
B34: 155000 | C34: 600.41 | D34: 520.79 | E34: =C34 -> 600.41 | F34: 520.79 | G34: 480.99 | H34: 1027.6 | I34: 1102.6 | J34: 1252.6 | K34: =L34-(C34-D34)-10.2 -> 207.8 | L34: 297.62 | M34: =N34-(F34-G34)-10.2 -> 247.62 | N34: =L34 -> 297.62
... B41: 190000 | C41: 701.03 | D41: 605.93 | E41: =C41 -> 701.03 | F41: 605.93 | G41: 558.39 | H41: 1192.24 | I41: 1267.24 | J41: 1417.24 | K41: =L41-(C41-D41)-10.2 -> 192.32 | L41: 297.62 | M41: =N41-(F41-G41)-10.2 -> 239.88 | N41: =L41 -> 297.62
B42: 195000 | C42: 715.4 | D42: 618.1 | E42: =C42 -> 715.4 | F42: 618.1 | G42: 569.45 | H42: 1215.76 | I42: 1290.76 | J42: 1440.76 | K42: =L42-(C42-D42)-10.2 -> 192.715 | L42: =(D42*$P$1)+(C42-D42)+10.2+100 -> 300.215 | M42: =N42-(F42-G42)-10.2 -> 241.365 | N42: =L42 -> 300.215
B43: 200000 | C43: 729.78 | D43: 630.26 | E43: =C43 -> 729.78 | F43: 630.26 | G43: 580.5 | H43: 1239.28 | I43: 1314.28 | J43: 1464.28 | K43: =L43-(C43-D43)-10.2 -> 194.539 | L43: =(D43*$P$1)+(C43-D43)+10.2+100 -> 304.259 | M43: =N43-(F43-G43)-10.2 -> 244.299 | N43: =L43 -> 304.259
B44: 205000 | C44: 744.15 | D44: 642.42 | E44: =C44 -> 744.15 | F44: 642.42 | G44: 591.56 | H44: 1262.8 | I44: 1337.8 | J44: 1487.8 | K44: =L44-(C44-D44)-10.2 -> 196.363 | L44: =(D44*$P$1)+(C44-D44)+10.2+100 -> 308.293 | M44: =N44-(F44-G44)-10.2 -> 247.233 | N44: =L44 -> 308.293
B45: 210000 | C45: 758.52 | D45: 654.59 | E45: =C45 -> 758.52 | F45: 654.59 | G45: 602.62 | H45: 1286.32 | I45: 1361.32 | J45: 1511.32 | K45: =L45-(C45-D45)-10.2 -> 198.1885 | L45: =(D45*$P$1)+(C45-D45)+10.2+100 -> 312.3185 | M45: =N45-(F45-G45)-10.2 -> 250.1485 | N45: =L45 -> 312.3185
B46: 215000 | C46: 772.9 | D46: 666.75 | E46: =C46 -> 772.9 | F46: 666.75 | G46: 613.67 | H46: 1309.84 | I46: 1384.84 | J46: 1534.84 | K46: =L46-(C46-D46)-10.2 -> 200.0125 | L46: =(D46*$P$1)+(C46-D46)+10.2+100 -> 316.3625 | M46: =N46-(F46-G46)-10.2 -> 253.0825 | N46: =L46 -> 316.3625
...

Sheet Cuotas niveladas
B10: Nombre:
B11: Monto solicitado | J11: 60000
B12: Tasa de interés | J12: 0.0175 | M12: =(J12*1.12) -> 0.0196
B13: Plazo (Meses) | J13: 60
B14: Seguro | J14: 0
B15: GPS | J15: 0
B16: Cuota | J16: =IFERROR(PMT(M12,J13,-J11),0) -> 1709.4019
A18: Mes | B18: Fecha de pago | C18: Saldo inicial | F18: Intereses | H18: IVA | J18: Interés + IVA | L18: Cuota | O18: Amortización | R18: Seguro | S18: GPS | T18: Saldo final | W18: Cuota mensual
B22: 44342 | C22: =J11 -> 60000 | F22: =C22*$J$12 -> 1050 | H22: =F22*0.12 -> 126 | J22: =F22+H22 -> 1176 | L22: =$J$16 -> 1709.4019 | O22: =L22-J22 -> 533.40193 | R22: =IF(C22="","",$J$14) -> 0 | S22: =IF(C22="","",$J$15) -> 0 | T22: =C22-O22 -> 59466.598 | W22: =IFERROR(L22+R22+S22,"") -> 1709.4019
A23: 1 | B23: =IF(C23="","",EDATE($B$22,A23)) -> 44373 | C23: =IF(C22="","",T22) -> 59466.598 | F23: =C23*$J$12 -> 1040.6655 | H23: =F23*0.12 -> 124.87986 | J23: =F23+H23 -> 1165.5453 | L23: =$J$16 -> 1709.4019 | O23: =L23-J23 -> 543.85661 | R23: =IF(C23="","",$J$14) -> 0 | S23: =IF(C23="","",$J$15) -> 0 | T23: =C23-O23 -> 58922.741 | W23: =IF(C23="","",$W$22) -> 1709.4019
A24: 2 | B24: =IF(C24="","",EDATE($B$22,A24)) -> 44403 | C24: =IF(C23="","",T23) -> 58922.741 | F24: =C24*$J$12 -> 1031.148 | H24: =F24*0.12 -> 123.73776 | J24: =F24+H24 -> 1154.8857 | L24: =$J$16 -> 1709.4019 | O24: =L24-J24 -> 554.5162 | R24: =IF(C24="","",$J$14) -> 0 | S24: =IF(C24="","",$J$15) -> 0 | T24: =C24-O24 -> 58368.225 | W24: =IF(C24="","",$W$22) -> 1709.4019
A25: 3 | B25: =IF(C25="","",EDATE($B$22,A25)) -> 44434 | C25: =IF(C24="","",T24) -> 58368.225 | F25: =C25*$J$12 -> 1021.4439 | H25: =F25*0.12 -> 122.57327 | J25: =F25+H25 -> 1144.0172 | L25: =$J$16 -> 1709.4019 | O25: =L25-J25 -> 565.38471 | R25: =IF(C25="","",$J$14) -> 0 | S25: =IF(C25="","",$J$15) -> 0 | T25: =C25-O25 -> 57802.841 | W25: =IF(C25="","",$W$22) -> 1709.4019
A26: 4 | B26: =IF(C26="","",EDATE($B$22,A26)) -> 44465 | C26: =IF(C25="","",T25) -> 57802.841 | F26: =C26*$J$12 -> 1011.5497 | H26: =F26*0.12 -> 121.38597 | J26: =F26+H26 -> 1132.9357 | L26: =$J$16 -> 1709.4019 | O26: =L26-J26 -> 576.46625 | R26: =IF(C26="","",$J$14) -> 0 | S26: =IF(C26="","",$J$15) -> 0 | T26: =C26-O26 -> 57226.374 | W26: =IF(C26="","",$W$22) -> 1709.4019
A27: 5 | B27: =IF(C27="","",EDATE($B$22,A27)) -> 44495 | C27: =IF(C26="","",T26) -> 57226.374 | F27: =C27*$J$12 -> 1001.4616 | H27: =F27*0.12 -> 120.17539 | J27: =IF(F27="","",F27+H27) -> 1121.6369 | L27: =$J$16 -> 1709.4019 | O27: =L27-J27 -> 587.76499 | R27: =IF(C27="","",$J$14) -> 0 | S27: =IF(C27="","",$J$15) -> 0 | T27: =C27-O27 -> 56638.609 | W27: =IF(C27="","",$W$22) -> 1709.4019
A28: 6 | B28: =IF(C28="","",EDATE($B$22,A28)) -> 44526 | C28: =IF(T27<=0.1,"",T27) -> 56638.609 | F28: =IF(C28="","",(C28*$J$12)) -> 991.17566 | H28: =IF(F28="","",(F28*0.12)) -> 118.94108 | J28: =IF(F28="","",F28+H28) -> 1110.1167 | L28: =IF(C28="","",$J$16) -> 1709.4019 | O28: =IF(C28="","",L28-J28) -> 599.28519 | R28: =IF(C28="","",$J$14) -> 0 | S28: =IF(C28="","",$J$15) -> 0 | T28: =IF(C28="","",C28-O28) -> 56039.324 | W28: =IF(C28="","",$W$22) -> 1709.4019
A29: 7 | B29: =IF(C29="","",EDATE($B$22,A29)) -> 44556 | C29: =IF(T28<=0.1,"",T28) -> 56039.324 | F29: =IF(C29="","",(C29*$J$12)) -> 980.68817 | H29: =IF(F29="","",(F29*0.12)) -> 117.68258 | J29: =IF(F29="","",F29+H29) -> 1098.3708 | L29: =IF(H29="","",$J$16) -> 1709.4019 | O29: =IF(C29="","",L29-J29) -> 611.03118 | R29: =IF(C29="","",$J$14) -> 0 | S29: =IF(C29="","",$J$15) -> 0 | T29: =IF(C29="","",C29-O29) -> 55428.293 | W29: =IF(C29="","",$W$22) -> 1709.4019
A30: 8 | B30: =IF(C30="","",EDATE($B$22,A30)) -> 44587 | C30: =IF(T29<=0.1,"",T29) -> 55428.293 | F30: =IF(C30="","",(C30*$J$12)) -> 969.99513 | H30: =IF(F30="","",(F30*0.12)) -> 116.39942 | J30: =IF(F30="","",F30+H30) -> 1086.3945 | L30: =IF(H30="","",$J$16) -> 1709.4019 | O30: =IF(C30="","",L30-J30) -> 623.00739 | R30: =IF(C30="","",$J$14) -> 0 | S30: =IF(C30="","",$J$15) -> 0 | T30: =IF(C30="","",C30-O30) -> 54805.286 | W30: =IF(C30="","",$W$22) -> 1709.4019
A31: 9 | B31: =IF(C31="","",EDATE($B$22,A31)) -> 44618 | C31: =IF(T30<=0.1,"",T30) -> 54805.286 | F31: =IF(C31="","",(C31*$J$12)) -> 959.0925 | H31: =IF(F31="","",(F31*0.12)) -> 115.0911 | J31: =IF(F31="","",F31+H31) -> 1074.1836 | L31: =IF(H31="","",$J$16) -> 1709.4019 | O31: =IF(C31="","",L31-J31) -> 635.21833 | R31: =IF(C31="","",$J$14) -> 0 | S31: =IF(C31="","",$J$15) -> 0 | T31: =IF(C31="","",C31-O31) -> 54170.067 | W31: =IF(C31="","",$W$22) -> 1709.4019
A32: 10 | B32: =IF(C32="","",EDATE($B$22,A32)) -> 44646 | C32: =IF(T31<=0.1,"",T31) -> 54170.067 | F32: =IF(C32="","",(C32*$J$12)) -> 947.97618 | H32: =IF(F32="","",(F32*0.12)) -> 113.75714 | J32: =IF(F32="","",F32+H32) -> 1061.7333 | L32: =IF(H32="","",$J$16) -> 1709.4019 | O32: =IF(C32="","",L32-J32) -> 647.66861 | R32: =IF(C32="","",$J$14) -> 0 | S32: =IF(C32="","",$J$15) -> 0 | T32: =IF(C32="","",C32-O32) -> 53522.399 | W32: =IF(C32="","",$W$22) -> 1709.4019
A33: 11 | B33: =IF(C33="","",EDATE($B$22,A33)) -> 44677 | C33: =IF(T32<=0.1,"",T32) -> 53522.399 | F33: =IF(C33="","",(C33*$J$12)) -> 936.64198 | H33: =IF(F33="","",(F33*0.12)) -> 112.39704 | J33: =IF(F33="","",F33+H33) -> 1049.039 | L33: =IF(H33="","",$J$16) -> 1709.4019 | O33: =IF(C33="","",L33-J33) -> 660.36292 | R33: =IF(C33="","",$J$14) -> 0 | S33: =IF(C33="","",$J$15) -> 0 | T33: =IF(C33="","",C33-O33) -> 52862.036 | W33: =IF(C33="","",$W$22) -> 1709.4019
A34: 12 | B34: =IF(C34="","",EDATE($B$22,A34)) -> 44707 | C34: =IF(T33<=0.1,"",T33) -> 52862.036 | F34: =IF(C34="","",(C34*$J$12)) -> 925.08562 | H34: =IF(F34="","",(F34*0.12)) -> 111.01027 | J34: =IF(F34="","",F34+H34) -> 1036.0959 | L34: =IF(H34="","",$J$16) -> 1709.4019 | O34: =IF(C34="","",L34-J34) -> 673.30603 | R34: =IF(C34="","",$J$14) -> 0 | S34: =IF(C34="","",$J$15) -> 0 | T34: =IF(C34="","",C34-O34) -> 52188.73 | W34: =IF(C34="","",$W$22) -> 1709.4019
A35: 13 | B35: =IF(C35="","",EDATE($B$22,A35)) -> 44738 | C35: =IF(T34<=0.1,"",T34) -> 52188.73 | F35: =IF(C35="","",(C35*$J$12)) -> 913.30277 | H35: =IF(F35="","",(F35*0.12)) -> 109.59633 | J35: =IF(F35="","",F35+H35) -> 1022.8991 | L35: =IF(H35="","",$J$16) -> 1709.4019 | O35: =IF(C35="","",L35-J35) -> 686.50283 | R35: =IF(C35="","",$J$14) -> 0 | S35: =IF(C35="","",$J$15) -> 0 | T35: =IF(C35="","",C35-O35) -> 51502.227 | W35: =IF(C35="","",$W$22) -> 1709.4019
A36: 14 | B36: =IF(C36="","",EDATE($B$22,A36)) -> 44768 | C36: =IF(T35<=0.1,"",T35) -> 51502.227 | F36: =IF(C36="","",(C36*$J$12)) -> 901.28897 | H36: =IF(F36="","",(F36*0.12)) -> 108.15468 | J36: =IF(F36="","",F36+H36) -> 1009.4436 | L36: =IF(H36="","",$J$16) -> 1709.4019 | O36: =IF(C36="","",L36-J36) -> 699.95828 | R36: =IF(C36="","",$J$14) -> 0 | S36: =IF(C36="","",$J$15) -> 0 | T36: =IF(C36="","",C36-O36) -> 50802.269 | W36: =IF(C36="","",$W$22) -> 1709.4019
A37: 15 | B37: =IF(C37="","",EDATE($B$22,A37)) -> 44799 | C37: =IF(T36<=0.1,"",T36) -> 50802.269 | F37: =IF(C37="","",(C37*$J$12)) -> 889.0397 | H37: =IF(F37="","",(F37*0.12)) -> 106.68476 | J37: =IF(F37="","",F37+H37) -> 995.72446 | L37: =IF(H37="","",$J$16) -> 1709.4019 | O37: =IF(C37="","",L37-J37) -> 713.67747 | R37: =IF(C37="","",$J$14) -> 0 | S37: =IF(C37="","",$J$15) -> 0 | T37: =IF(C37="","",C37-O37) -> 50088.591 | W37: =IF(C37="","",$W$22) -> 1709.4019
A38: 16 | B38: =IF(C38="","",EDATE($B$22,A38)) -> 44830 | C38: =IF(T37<=0.1,"",T37) -> 50088.591 | F38: =IF(C38="","",(C38*$J$12)) -> 876.55034 | H38: =IF(F38="","",(F38*0.12)) -> 105.18604 | J38: =IF(F38="","",F38+H38) -> 981.73639 | L38: =IF(H38="","",$J$16) -> 1709.4019 | O38: =IF(C38="","",L38-J38) -> 727.66554 | R38: =IF(C38="","",$J$14) -> 0 | S38: =IF(C38="","",$J$15) -> 0 | T38: =IF(C38="","",C38-O38) -> 49360.926 | W38: =IF(C38="","",$W$22) -> 1709.4019
A39: 17 | B39: =IF(C39="","",EDATE($B$22,A39)) -> 44860 | C39: =IF(T38<=0.1,"",T38) -> 49360.926 | F39: =IF(C39="","",(C39*$J$12)) -> 863.8162 | H39: =IF(F39="","",(F39*0.12)) -> 103.65794 | J39: =IF(F39="","",F39+H39) -> 967.47414 | L39: =IF(H39="","",$J$16) -> 1709.4019 | O39: =IF(C39="","",L39-J39) -> 741.92779 | R39: =IF(C39="","",$J$14) -> 0 | S39: =IF(C39="","",$J$15) -> 0 | T39: =IF(C39="","",C39-O39) -> 48618.998 | W39: =IF(C39="","",$W$22) -> 1709.4019
A40: 18 | B40: =IF(C40="","",EDATE($B$22,A40)) -> 44891 | C40: =IF(T39<=0.1,"",T39) -> 48618.998 | F40: =IF(C40="","",(C40*$J$12)) -> 850.83246 | H40: =IF(F40="","",(F40*0.12)) -> 102.0999 | J40: =IF(F40="","",F40+H40) -> 952.93236 | L40: =IF(H40="","",$J$16) -> 1709.4019 | O40: =IF(C40="","",L40-J40) -> 756.46957 | R40: =IF(C40="","",$J$14) -> 0 | S40: =IF(C40="","",$J$15) -> 0 | T40: =IF(C40="","",C40-O40) -> 47862.528 | W40: =IF(C40="","",$W$22) -> 1709.4019
... A69: 47 | B69: =IF(C69="","",EDATE($B$22,A69)) -> 45773 | C69: =IF(T68<=0.1,"",T68) -> 19450.176 | F69: =IF(C69="","",(C69*$J$12)) -> 340.37807 | H69: =IF(F69="","",(F69*0.12)) -> 40.845369 | J69: =IF(F69="","",F69+H69) -> 381.22344 | L69: =IF(H69="","",$J$16) -> 1709.4019 | O69: =IF(C69="","",L69-J69) -> 1328.1785 | R69: =IF(C69="","",$J$14) -> 0 | S69: =IF(C69="","",$J$15) -> 0 | T69: =IF(C69="","",C69-O69) -> 18121.997 | W69: =IF(C69="","",$W$22) -> 1709.4019
L70: =IF(H70="","",$J$16) | R70: =IF(C70="","",$J$14) | S70: =IF(C70="","",$J$15) | T70: =IF(C70="","",C70-O70)

Sheet Detalle Cuota especial
C7: Capital | E7: 40000
C8: Tasa de interés | E8: 0.05 | L8: =(E8*1.12) -> 0.056 | AA8: Utilidad Neta Inversor
C9: Plazo (Meses) | E9: 6 | AB9: =SUM(AD18:AD52) -> 45570
C10: Cuota mensual (sin servicios) | E10: =G18+I18+E11+E12 -> 2735
C11: Seguro | E11: 350
C12: GPS | E12: 145
C13: Cuota mensual | E13: =SUM(E10:G12) -> 3230
C14: Inversionista | E14: 0.7
C15: Cash-in | E15: 0.3
AB16: Con impuestos | AD16: Sin impuestos
A17: No. Cuota | B17: Mes | C17: Fecha de pago | D17: Saldo inicial | G17: Intereses | I17: IVA | K17: Interés + IVA | M17: Cuota | P17: Amortización | S17: Seguro | T17: GPS | U17: Saldo final | X17: Cuota mensual | AA17: ISR | AB17: Inversionista | AC17: Cash-In | AD17: Inversionista | AE17: Cash-in
A18: 1 | C18: 43940 | D18: =E7 -> 40000 | G18: =D18*$E$8 -> 2000 | I18: =G18*0.12 -> 240 | K18: =G18+I18 -> 2240 | M18: =G18+I18+$E$11+$E$12 -> 2735 | P18: 0 | S18: =IF(D18="","",$E$11) -> 350 | T18: =IF(D18="","",$E$12) -> 145 | U18: =D18-P18 -> 40000 | X18: =IFERROR(M18+S18+T18,"") -> 3230 | AA18: =G18*0.07 -> 140 | AB18: =(G18+I18)*$E$14 -> 1568 | AC18: =(G18+I18)*$E$15 -> 672 | AD18: =(G18-AA18)*$E$14 -> 1302 | AE18: =(G18-AA18)*$E$15 -> 558
A19: =IF(D19="","",B19+1) -> 2 | B19: 1 | C19: =IF(D19="","",EDATE(C18,B19)) -> 43970 | D19: =IF(U18<=0.1,"",U18) -> 40000 | G19: =IF(D19="","",(D19*$E$8)) -> 2000 | I19: =IF(G19="","",(G19*0.12)) -> 240 | K19: =IF(G19="","",G19+I19) -> 2240 | M19: =IF(I19="","",G19+I19+$E$11+$E$12) -> 2735 | P19: 0 | S19: =IF(D19="","",$E$11) -> 350 | T19: =IF(D19="","",$E$12) -> 145 | U19: =IF(P19="","",D19-P19) -> 40000 | X19: =IF(D19="","",$X$18) -> 3230 | AA19: =IF(G19="","",(G19*0.07)) -> 140 | AB19: =IF(G19="","",(G19+I19)*$E$14) -> 1568 | AC19: =IF(G19="","",(G19+I19)*$E$15) -> 672 | AD19: =IF(G19="","",(G19-AA19)*$E$14) -> 1302 | AE19: =IF(G19="","",(G19-AA19)*$E$15) -> 558
A20: =IF(D20="","",B20+1) -> 3 | B20: 2 | C20: =IF(D20="","",EDATE(C19,B20)) -> 44031 | D20: =IF(U19<=0.1,"",U19) -> 40000 | G20: =IF(D20="","",(D20*$E$8)) -> 2000 | I20: =IF(G20="","",(G20*0.12)) -> 240 | K20: =IF(G20="","",G20+I20) -> 2240 | M20: =IF(I20="","",G20+I20+$E$11+$E$12) -> 2735 | P20: 0 | S20: =IF(D20="","",$E$11) -> 350 | T20: =IF(D20="","",$E$12) -> 145 | U20: =IF(P20="","",D20-P20) -> 40000 | X20: =IF(D20="","",$X$18) -> 3230 | AA20: =IF(G20="","",(G20*0.07)) -> 140 | AB20: =IF(G20="","",(G20+I20)*$E$14) -> 1568 | AC20: =IF(G20="","",(G20+I20)*$E$15) -> 672 | AD20: =IF(G20="","",(G20-AA20)*$E$14) -> 1302 | AE20: =IF(G20="","",(G20-AA20)*$E$15) -> 558
A21: =IF(D21="","",B21+1) -> 4 | B21: 3 | C21: =IF(D21="","",EDATE(C20,B21)) -> 44123 | D21: =IF(U20<=0.1,"",U20) -> 40000 | G21: =IF(D21="","",(D21*$E$8)) -> 2000 | I21: =IF(G21="","",(G21*0.12)) -> 240 | K21: =IF(G21="","",G21+I21) -> 2240 | M21: =IF(I21="","",G21+I21+$E$11+$E$12) -> 2735 | P21: 0 | S21: =IF(D21="","",$E$11) -> 350 | T21: =IF(D21="","",$E$12) -> 145 | U21: =IF(P21="","",D21-P21) -> 40000 | X21: =IF(D21="","",$X$18) -> 3230 | AA21: =IF(G21="","",(G21*0.07)) -> 140 | AB21: =IF(G21="","",(G21+I21)*$E$14) -> 1568 | AC21: =IF(G21="","",(G21+I21)*$E$15) -> 672 | AD21: =IF(G21="","",(G21-AA21)*$E$14) -> 1302 | AE21: =IF(G21="","",(G21-AA21)*$E$15) -> 558
A22: =IF(D22="","",B22+1) -> 5 | B22: 4 | C22: =IF(D22="","",EDATE(C21,B22)) -> 44246 | D22: =IF(U21<=0.1,"",U21) -> 40000 | G22: =IF(D22="","",(D22*$E$8)) -> 2000 | I22: =IF(G22="","",(G22*0.12)) -> 240 | K22: =IF(G22="","",G22+I22) -> 2240 | M22: =IF(I22="","",G22+I22+$E$11+$E$12) -> 2735 | P22: 0 | S22: =IF(P22="","",$E$11) -> 350 | T22: =IF(P22="","",$E$12) -> 145 | U22: =IF(P22="","",D22-P22) -> 40000 | X22: =IF(P22="","",$X$18) -> 3230 | AA22: =IF(G22="","",(G22*0.07)) -> 140 | AB22: =IF(G22="","",(G22+I22)*$E$14) -> 1568 | AC22: =IF(G22="","",(G22+I22)*$E$15) -> 672 | AD22: =IF(G22="","",(G22-AA22)*$E$14) -> 1302 | AE22: =IF(G22="","",(G22-AA22)*$E$15) -> 558
A23: =IF(D23="","",B23+1) -> 6 | B23: 5 | C23: =IF(D23="","",EDATE(C22,B23)) -> 44396 | D23: =IF(U22<=0.1,"",U22) -> 40000 | G23: =IF(D23="","",(D23*$E$8)) -> 2000 | I23: =IF(G23="","",(G23*0.12)) -> 240 | K23: =IF(G23="","",G23+I23) -> 2240 | M23: =IF(I23="","",G23+I23+$E$11+$E$12) -> 2735 | P23: 0 | S23: =IF(P23="","",$E$11) -> 350 | T23: =IF(P23="","",$E$12) -> 145 | U23: =IF(P23="","",D23-P23) -> 40000 | X23: =IF(P23="","",$X$18) -> 3230 | AA23: =IF(G23="","",(G23*0.07)) -> 140 | AB23: =IF(G23="","",(G23+I23)*$E$14) -> 1568 | AC23: =IF(G23="","",(G23+I23)*$E$15) -> 672 | AD23: =IF(G23="","",(G23-AA23)*$E$14) -> 1302 | AE23: =IF(G23="","",(G23-AA23)*$E$15) -> 558
A24: =IF(D24="","",B24+1) -> 7 | B24: 6 | C24: =IF(D24="","",EDATE(C23,B24)) -> 44580 | D24: =IF(U23<=0.1,"",U23) -> 40000 | G24: =IF(D24="","",(D24*$E$8)) -> 2000 | I24: =IF(G24="","",(G24*0.12)) -> 240 | K24: =IF(G24="","",G24+I24) -> 2240 | M24: =IF(I24="","",G24+I24+$E$11+$E$12) -> 2735 | P24: 0 | S24: =IF(P24="","",$E$11) -> 350 | T24: =IF(P24="","",$E$12) -> 145 | U24: =IF(P24="","",D24-P24) -> 40000 | X24: =IF(P24="","",$X$18) -> 3230 | AA24: =IF(G24="","",(G24*0.07)) -> 140 | AB24: =IF(G24="","",(G24+I24)*$E$14) -> 1568 | AC24: =IF(G24="","",(G24+I24)*$E$15) -> 672 | AD24: =IF(G24="","",(G24-AA24)*$E$14) -> 1302 | AE24: =IF(G24="","",(G24-AA24)*$E$15) -> 558
A25: =IF(D25="","",B25+1) -> 8 | B25: 7 | C25: =IF(D25="","",EDATE(C24,B25)) -> 44792 | D25: =IF(U24<=0.1,"",U24) -> 40000 | G25: =IF(D25="","",(D25*$E$8)) -> 2000 | I25: =IF(G25="","",(G25*0.12)) -> 240 | K25: =IF(G25="","",G25+I25) -> 2240 | M25: =IF(I25="","",G25+I25+$E$11+$E$12) -> 2735 | P25: 0 | S25: =IF(P25="","",$E$11) -> 350 | T25: =IF(P25="","",$E$12) -> 145 | U25: =IF(P25="","",D25-P25) -> 40000 | X25: =IF(P25="","",$X$18) -> 3230 | AA25: =IF(G25="","",(G25*0.07)) -> 140 | AB25: =IF(G25="","",(G25+I25)*$E$14) -> 1568 | AC25: =IF(G25="","",(G25+I25)*$E$15) -> 672 | AD25: =IF(G25="","",(G25-AA25)*$E$14) -> 1302 | AE25: =IF(G25="","",(G25-AA25)*$E$15) -> 558
A26: =IF(D26="","",B26+1) -> 9 | B26: 8 | C26: =IF(D26="","",EDATE(C25,B26)) -> 45035 | D26: =IF(U25<=0.1,"",U25) -> 40000 | G26: =IF(D26="","",(D26*$E$8)) -> 2000 | I26: =IF(G26="","",(G26*0.12)) -> 240 | K26: =IF(G26="","",G26+I26) -> 2240 | M26: =IF(I26="","",G26+I26+$E$11+$E$12) -> 2735 | P26: 0 | S26: =IF(P26="","",$E$11) -> 350 | T26: =IF(P26="","",$E$12) -> 145 | U26: =IF(P26="","",D26-P26) -> 40000 | X26: =IF(P26="","",$X$18) -> 3230 | AA26: =IF(G26="","",(G26*0.07)) -> 140 | AB26: =IF(G26="","",(G26+I26)*$E$14) -> 1568 | AC26: =IF(G26="","",(G26+I26)*$E$15) -> 672 | AD26: =IF(G26="","",(G26-AA26)*$E$14) -> 1302 | AE26: =IF(G26="","",(G26-AA26)*$E$15) -> 558
A27: =IF(D27="","",B27+1) -> 10 | B27: 9 | C27: =IF(D27="","",EDATE(C26,B27)) -> 45310 | D27: =IF(U26<=0.1,"",U26) -> 40000 | G27: =IF(D27="","",(D27*$E$8)) -> 2000 | I27: =IF(G27="","",(G27*0.12)) -> 240 | K27: =IF(G27="","",G27+I27) -> 2240 | M27: =IF(I27="","",G27+I27+$E$11+$E$12) -> 2735 | P27: 0 | S27: =IF(P27="","",$E$11) -> 350 | T27: =IF(P27="","",$E$12) -> 145 | U27: =IF(P27="","",D27-P27) -> 40000 | X27: =IF(P27="","",$X$18) -> 3230 | AA27: =IF(G27="","",(G27*0.07)) -> 140 | AB27: =IF(G27="","",(G27+I27)*$E$14) -> 1568 | AC27: =IF(G27="","",(G27+I27)*$E$15) -> 672 | AD27: =IF(G27="","",(G27-AA27)*$E$14) -> 1302 | AE27: =IF(G27="","",(G27-AA27)*$E$15) -> 558
A28: =IF(D28="","",B28+1) -> 11 | B28: 10 | C28: =IF(D28="","",EDATE(C27,B28)) -> 45615 | D28: =IF(U27<=0.1,"",U27) -> 40000 | G28: =IF(D28="","",(D28*$E$8)) -> 2000 | I28: =IF(G28="","",(G28*0.12)) -> 240 | K28: =IF(G28="","",G28+I28) -> 2240 | M28: =IF(I28="","",G28+I28+$E$11+$E$12) -> 2735 | P28: 0 | S28: =IF(P28="","",$E$11) -> 350 | T28: =IF(P28="","",$E$12) -> 145 | U28: =IF(P28="","",D28-P28) -> 40000 | X28: =IF(P28="","",$X$18) -> 3230 | AA28: =IF(G28="","",(G28*0.07)) -> 140 | AB28: =IF(G28="","",(G28+I28)*$E$14) -> 1568 | AC28: =IF(G28="","",(G28+I28)*$E$15) -> 672 | AD28: =IF(G28="","",(G28-AA28)*$E$14) -> 1302 | AE28: =IF(G28="","",(G28-AA28)*$E$15) -> 558
A29: =IF(D29="","",B29+1) -> 12 | B29: 11 | C29: =IF(D29="","",EDATE(C28,B29)) -> 45949 | D29: =IF(U28<=0.1,"",U28) -> 40000 | G29: =IF(D29="","",(D29*$E$8)) -> 2000 | I29: =IF(G29="","",(G29*0.12)) -> 240 | K29: =IF(G29="","",G29+I29) -> 2240 | M29: =IF(I29="","",G29+I29+$E$11+$E$12) -> 2735 | P29: 0 | S29: =IF(P29="","",$E$11) -> 350 | T29: =IF(P29="","",$E$12) -> 145 | U29: =IF(P29="","",D29-P29) -> 40000 | X29: =IF(P29="","",$X$18) -> 3230 | AA29: =IF(G29="","",(G29*0.07)) -> 140 | AB29: =IF(G29="","",(G29+I29)*$E$14) -> 1568 | AC29: =IF(G29="","",(G29+I29)*$E$15) -> 672 | AD29: =IF(G29="","",(G29-AA29)*$E$14) -> 1302 | AE29: =IF(G29="","",(G29-AA29)*$E$15) -> 558
A30: =IF(D30="","",B30+1) -> 13 | B30: 12 | C30: =IF(D30="","",EDATE(C29,B30)) -> 46314 | D30: =IF(U29<=0.1,"",U29) -> 40000 | G30: =IF(D30="","",(D30*$E$8)) -> 2000 | I30: =IF(G30="","",(G30*0.12)) -> 240 | K30: =IF(G30="","",G30+I30) -> 2240 | M30: =IF(I30="","",G30+I30+$E$11+$E$12) -> 2735 | P30: 0 | S30: =IF(P30="","",$E$11) -> 350 | T30: =IF(P30="","",$E$12) -> 145 | U30: =IF(P30="","",D30-P30) -> 40000 | X30: =IF(P30="","",$X$18) -> 3230 | AA30: =IF(G30="","",(G30*0.07)) -> 140 | AB30: =IF(G30="","",(G30+I30)*$E$14) -> 1568 | AC30: =IF(G30="","",(G30+I30)*$E$15) -> 672 | AD30: =IF(G30="","",(G30-AA30)*$E$14) -> 1302 | AE30: =IF(G30="","",(G30-AA30)*$E$15) -> 558
A31: =IF(D31="","",B31+1) -> 14 | B31: 13 | C31: =IF(D31="","",EDATE(C30,B31)) -> 46710 | D31: =IF(U30<=0.1,"",U30) -> 40000 | G31: =IF(D31="","",(D31*$E$8)) -> 2000 | I31: =IF(G31="","",(G31*0.12)) -> 240 | K31: =IF(G31="","",G31+I31) -> 2240 | M31: =IF(I31="","",G31+I31+$E$11+$E$12) -> 2735 | P31: 0 | S31: =IF(P31="","",$E$11) -> 350 | T31: =IF(P31="","",$E$12) -> 145 | U31: =IF(P31="","",D31-P31) -> 40000 | X31: =IF(P31="","",$X$18) -> 3230 | AA31: =IF(G31="","",(G31*0.07)) -> 140 | AB31: =IF(G31="","",(G31+I31)*$E$14) -> 1568 | AC31: =IF(G31="","",(G31+I31)*$E$15) -> 672 | AD31: =IF(G31="","",(G31-AA31)*$E$14) -> 1302 | AE31: =IF(G31="","",(G31-AA31)*$E$15) -> 558
A32: =IF(D32="","",B32+1) -> 15 | B32: 14 | C32: =IF(D32="","",EDATE(C31,B32)) -> 47137 | D32: =IF(U31<=0.1,"",U31) -> 40000 | G32: =IF(D32="","",(D32*$E$8)) -> 2000 | I32: =IF(G32="","",(G32*0.12)) -> 240 | K32: =IF(G32="","",G32+I32) -> 2240 | M32: =IF(I32="","",G32+I32+$E$11+$E$12) -> 2735 | P32: 0 | S32: =IF(P32="","",$E$11) -> 350 | T32: =IF(P32="","",$E$12) -> 145 | U32: =IF(P32="","",D32-P32) -> 40000 | X32: =IF(P32="","",$X$18) -> 3230 | AA32: =IF(G32="","",(G32*0.07)) -> 140 | AB32: =IF(G32="","",(G32+I32)*$E$14) -> 1568 | AC32: =IF(G32="","",(G32+I32)*$E$15) -> 672 | AD32: =IF(G32="","",(G32-AA32)*$E$14) -> 1302 | AE32: =IF(G32="","",(G32-AA32)*$E$15) -> 558
A33: =IF(D33="","",B33+1) -> 16 | B33: 15 | C33: =IF(D33="","",EDATE(C32,B33)) -> 47592 | D33: =IF(U32<=0.1,"",U32) -> 40000 | G33: =IF(D33="","",(D33*$E$8)) -> 2000 | I33: =IF(G33="","",(G33*0.12)) -> 240 | K33: =IF(G33="","",G33+I33) -> 2240 | M33: =IF(I33="","",G33+I33+$E$11+$E$12) -> 2735 | P33: 0 | S33: =IF(P33="","",$E$11) -> 350 | T33: =IF(P33="","",$E$12) -> 145 | U33: =IF(P33="","",D33-P33) -> 40000 | X33: =IF(P33="","",$X$18) -> 3230 | AA33: =IF(G33="","",(G33*0.07)) -> 140 | AB33: =IF(G33="","",(G33+I33)*$E$14) -> 1568 | AC33: =IF(G33="","",(G33+I33)*$E$15) -> 672 | AD33: =IF(G33="","",(G33-AA33)*$E$14) -> 1302 | AE33: =IF(G33="","",(G33-AA33)*$E$15) -> 558
A34: =IF(D34="","",B34+1) -> 17 | B34: 16 | C34: =IF(D34="","",EDATE(C33,B34)) -> 48079 | D34: =IF(U33<=0.1,"",U33) -> 40000 | G34: =IF(D34="","",(D34*$E$8)) -> 2000 | I34: =IF(G34="","",(G34*0.12)) -> 240 | K34: =IF(G34="","",G34+I34) -> 2240 | M34: =IF(I34="","",G34+I34+$E$11+$E$12) -> 2735 | P34: 0 | S34: =IF(P34="","",$E$11) -> 350 | T34: =IF(P34="","",$E$12) -> 145 | U34: =IF(P34="","",D34-P34) -> 40000 | X34: =IF(P34="","",$X$18) -> 3230 | AA34: =IF(G34="","",(G34*0.07)) -> 140 | AB34: =IF(G34="","",(G34+I34)*$E$14) -> 1568 | AC34: =IF(G34="","",(G34+I34)*$E$15) -> 672 | AD34: =IF(G34="","",(G34-AA34)*$E$14) -> 1302 | AE34: =IF(G34="","",(G34-AA34)*$E$15) -> 558
A35: =IF(D35="","",B35+1) -> 18 | B35: 17 | C35: =IF(D35="","",EDATE(C34,B35)) -> 48598 | D35: =IF(U34<=0.1,"",U34) -> 40000 | G35: =IF(D35="","",(D35*$E$8)) -> 2000 | I35: =IF(G35="","",(G35*0.12)) -> 240 | K35: =IF(G35="","",G35+I35) -> 2240 | M35: =IF(I35="","",G35+I35+$E$11+$E$12) -> 2735 | P35: 0 | S35: =IF(D35="","",$E$11) -> 350 | T35: =IF(P35="","",$E$12) -> 145 | U35: =IF(P35="","",D35-P35) -> 40000 | X35: =IF(P35="","",$X$18) -> 3230 | AA35: =IF(G35="","",(G35*0.07)) -> 140 | AB35: =IF(G35="","",(G35+I35)*$E$14) -> 1568 | AC35: =IF(G35="","",(G35+I35)*$E$15) -> 672 | AD35: =IF(G35="","",(G35-AA35)*$E$14) -> 1302 | AE35: =IF(G35="","",(G35-AA35)*$E$15) -> 558
A36: =IF(D36="","",B36+1) -> 19 | B36: 18 | C36: =IF(D36="","",EDATE(C35,B36)) -> 49144 | D36: =IF(U35<=0.1,"",U35) -> 40000 | G36: =IF(D36="","",(D36*$E$8)) -> 2000 | I36: =IF(G36="","",(G36*0.12)) -> 240 | K36: =IF(G36="","",G36+I36) -> 2240 | M36: =IF(I36="","",G36+I36+$E$11+$E$12) -> 2735 | P36: 0 | S36: =IF(D36="","",$E$11) -> 350 | T36: =IF(D36="","",$E$12) -> 145 | U36: =IF(P36="","",D36-P36) -> 40000 | X36: =IF(D36="","",$X$18) -> 3230 | AA36: =IF(G36="","",(G36*0.07)) -> 140 | AB36: =IF(G36="","",(G36+I36)*$E$14) -> 1568 | AC36: =IF(G36="","",(G36+I36)*$E$15) -> 672 | AD36: =IF(G36="","",(G36-AA36)*$E$14) -> 1302 | AE36: =IF(G36="","",(G36-AA36)*$E$15) -> 558
A37: =IF(D37="","",B37+1) -> 20 | B37: 19 | C37: =IF(D37="","",EDATE(C36,B37)) -> 49724 | D37: =IF(U36<=0.1,"",U36) -> 40000 | G37: =IF(D37="","",(D37*$E$8)) -> 2000 | I37: =IF(G37="","",(G37*0.12)) -> 240 | K37: =IF(G37="","",G37+I37) -> 2240 | M37: =IF(I37="","",G37+I37+$E$11+$E$12) -> 2735 | P37: 0 | S37: =IF(D37="","",$E$11) -> 350 | T37: =IF(D37="","",$E$12) -> 145 | U37: =IF(P37="","",D37-P37) -> 40000 | X37: =IF(D37="","",$X$18) -> 3230 | AA37: =IF(G37="","",(G37*0.07)) -> 140 | AB37: =IF(G37="","",(G37+I37)*$E$14) -> 1568 | AC37: =IF(G37="","",(G37+I37)*$E$15) -> 672 | AD37: =IF(G37="","",(G37-AA37)*$E$14) -> 1302 | AE37: =IF(G37="","",(G37-AA37)*$E$15) -> 558
A38: =IF(D38="","",B38+1) -> 21 | B38: 20 | C38: =IF(D38="","",EDATE(C37,B38)) -> 50332 | D38: =IF(U37<=0.1,"",U37) -> 40000 | G38: =IF(D38="","",(D38*$E$8)) -> 2000 | I38: =IF(G38="","",(G38*0.12)) -> 240 | K38: =IF(G38="","",G38+I38) -> 2240 | M38: =IF(I38="","",G38+I38+$E$11+$E$12) -> 2735 | P38: 0 | S38: =IF(D38="","",$E$11) -> 350 | T38: =IF(D38="","",$E$12) -> 145 | U38: =IF(P38="","",D38-P38) -> 40000 | X38: =IF(D38="","",$X$18) -> 3230 | AA38: =IF(G38="","",(G38*0.07)) -> 140 | AB38: =IF(G38="","",(G38+I38)*$E$14) -> 1568 | AC38: =IF(G38="","",(G38+I38)*$E$15) -> 672 | AD38: =IF(G38="","",(G38-AA38)*$E$14) -> 1302 | AE38: =IF(G38="","",(G38-AA38)*$E$15) -> 558
A39: =IF(D39="","",B39+1) -> 22 | B39: 21 | C39: =IF(D39="","",EDATE(C38,B39)) -> 50970 | D39: =IF(U38<=0.1,"",U38) -> 40000 | G39: =IF(D39="","",(D39*$E$8)) -> 2000 | I39: =IF(G39="","",(G39*0.12)) -> 240 | K39: =IF(G39="","",G39+I39) -> 2240 | M39: =IF(I39="","",G39+I39+$E$11+$E$12) -> 2735 | P39: 0 | S39: =IF(D39="","",$E$11) -> 350 | T39: =IF(D39="","",$E$12) -> 145 | U39: =IF(P39="","",D39-P39) -> 40000 | X39: =IF(D39="","",$X$18) -> 3230 | AA39: =IF(G39="","",(G39*0.07)) -> 140 | AB39: =IF(G39="","",(G39+I39)*$E$14) -> 1568 | AC39: =IF(G39="","",(G39+I39)*$E$15) -> 672 | AD39: =IF(G39="","",(G39-AA39)*$E$14) -> 1302 | AE39: =IF(G39="","",(G39-AA39)*$E$15) -> 558
A40: =IF(D40="","",B40+1) -> 23 | B40: 22 | C40: =IF(D40="","",EDATE(C39,B40)) -> 51640 | D40: =IF(U39<=0.1,"",U39) -> 40000 | G40: =IF(D40="","",(D40*$E$8)) -> 2000 | I40: =IF(G40="","",(G40*0.12)) -> 240 | K40: =IF(G40="","",G40+I40) -> 2240 | M40: =IF(I40="","",G40+I40+$E$11+$E$12) -> 2735 | P40: 0 | S40: =IF(D40="","",$E$11) -> 350 | T40: =IF(D40="","",$E$12) -> 145 | U40: =IF(P40="","",D40-P40) -> 40000 | X40: =IF(D40="","",$X$18) -> 3230 | AA40: =IF(G40="","",(G40*0.07)) -> 140 | AB40: =IF(G40="","",(G40+I40)*$E$14) -> 1568 | AC40: =IF(G40="","",(G40+I40)*$E$15) -> 672 | AD40: =IF(G40="","",(G40-AA40)*$E$14) -> 1302 | AE40: =IF(G40="","",(G40-AA40)*$E$15) -> 558
A41: =IF(D41="","",B41+1) -> 24 | B41: 23 | C41: =IF(D41="","",EDATE(C40,B41)) -> 52340 | D41: =IF(U40<=0.1,"",U40) -> 40000 | G41: =IF(D41="","",(D41*$E$8)) -> 2000 | I41: =IF(G41="","",(G41*0.12)) -> 240 | K41: =IF(G41="","",G41+I41) -> 2240 | M41: =IF(I41="","",G41+I41+$E$11+$E$12) -> 2735 | P41: 0 | S41: =IF(D41="","",$E$11) -> 350 | T41: =IF(D41="","",$E$12) -> 145 | U41: =IF(P41="","",D41-P41) -> 40000 | X41: =IF(D41="","",$X$18) -> 3230 | AA41: =IF(G41="","",(G41*0.07)) -> 140 | AB41: =IF(G41="","",(G41+I41)*$E$14) -> 1568 | AC41: =IF(G41="","",(G41+I41)*$E$15) -> 672 | AD41: =IF(G41="","",(G41-AA41)*$E$14) -> 1302 | AE41: =IF(G41="","",(G41-AA41)*$E$15) -> 558
A42: =IF(D42="","",B42+1) -> 25 | B42: 24 | C42: =IF(D42="","",EDATE(C41,B42)) -> 53071 | D42: =IF(U41<=0.1,"",U41) -> 40000 | G42: =IF(D42="","",(D42*$E$8)) -> 2000 | I42: =IF(G42="","",(G42*0.12)) -> 240 | K42: =IF(G42="","",G42+I42) -> 2240 | M42: =IF(I42="","",G42+I42+$E$11+$E$12) -> 2735 | P42: 0 | S42: =IF(D42="","",$E$11) -> 350 | T42: =IF(D42="","",$E$12) -> 145 | U42: =IF(P42="","",D42-P42) -> 40000 | X42: =IF(D42="","",$X$18) -> 3230 | AA42: =IF(G42="","",(G42*0.07)) -> 140 | AB42: =IF(G42="","",(G42+I42)*$E$14) -> 1568 | AC42: =IF(G42="","",(G42+I42)*$E$15) -> 672 | AD42: =IF(G42="","",(G42-AA42)*$E$14) -> 1302 | AE42: =IF(G42="","",(G42-AA42)*$E$15) -> 558
A43: =IF(D43="","",B43+1) -> 26 | B43: 25 | C43: =IF(D43="","",EDATE(C42,B43)) -> 53831 | D43: =IF(U42<=0.1,"",U42) -> 40000 | G43: =IF(D43="","",(D43*$E$8)) -> 2000 | I43: =IF(G43="","",(G43*0.12)) -> 240 | K43: =IF(G43="","",G43+I43) -> 2240 | M43: =IF(I43="","",G43+I43+$E$11+$E$12) -> 2735 | P43: 0 | S43: =IF(D43="","",$E$11) -> 350 | T43: =IF(D43="","",$E$12) -> 145 | U43: =IF(P43="","",D43-P43) -> 40000 | X43: =IF(D43="","",$X$18) -> 3230 | AA43: =IF(G43="","",(G43*0.07)) -> 140 | AB43: =IF(G43="","",(G43+I43)*$E$14) -> 1568 | AC43: =IF(G43="","",(G43+I43)*$E$15) -> 672 | AD43: =IF(G43="","",(G43-AA43)*$E$14) -> 1302 | AE43: =IF(G43="","",(G43-AA43)*$E$15) -> 558
