Workbook

Sheet Hoja1
B3: Nombre del propietario | C3: =IF(#REF!="","",#REF!) -> #REF!
B4: Nombre del deudor | C4: =#REF!&Hoja1!C2&#REF!&Hoja1!C2&#REF!&Hoja1!C2&#REF! -> #REF!

Sheet Detalle vehiculo
B1: Detalle de crédito sobre vehiculo
B4: Nombre del Propietario:
B5: Nombre del deudor:
B6: Nit del deudor:
B7: Garantía
B8: Datos:
B9: Inversionista:
A11: ► | B11: MONTO SOLICITADO EN QUETZALES: | G11: 43000
E13: % | F13: IVA
B14: Tasa de Interés: | C14: 0.03 | D14: Inversionista | E14: =(G11*C14)*70% -> 903 | F14: =E14*0.12 -> 108.36 | G14: =G11*C14*C15 -> 0
A15: ► | B15: MES INTERES ANTICIPADO | D15: Empresa | E15: =(G11*C14)*30% -> 387 | F15: =E15*0.12 -> 46.44 | G15: =G14*12/100 -> 0
D16: Inversionista | E16: =E14+F14 -> 1011.36 | G16: =SUM(G14:G15) -> 0
D17: Empresa | E17: =E15+F15 -> 433.44
A18: ► | B18: COMISION Y GASTOS DE REGISTRO
C19: Descontado
B20: ROYALTY | C20: SI | E20: 0.04 | F20: =G11*E20 -> 1720
B21: Free lance | C21: SI | E21: 0.01 | F21: =(G11)*E21 -> 430
B22: Free Lance | C22: NO | E22: 0 | F22: =G11*E22 -> 0
B23: Inspección | C23: NO | F23: 0
B24: GPS | C24: NO | F24: 0
B25: Seguro INREXSA | C25: SI | F25: ='Cotizador interno'!K17 -> 245
B26: Membresía | C26: SI | F26: ='Cotizador interno'!K19 -> 374.789
B27: Gastos Administrativos | C27: SI | F27: 600
B28: Intereses | C28: SI | F28: ='Cotizador interno'!K25 -> 1444.8 | G28: =F20+F21+F27+F24+F25+F26+F28 -> 4814.589
B30: OTROS DESCUENTOS
B31: Multas | C31: NO | F31: 0
B32: Multas | C32: NO | F32: 0
B33: Copia de llave | C33: NO | F33: 0
B34: Diferencia de Copia de llave | C34: NO | F34: 0
B35: Impuesto circulación, 2025 | C35: NO | F35: 0
B36: Traspaso de vehículo | C36: SI | F36: 1300
B37: Garantía mobiliaria | C37: SI | F37: 400
G38: =SUM(F31:F37) -> 1700
B40: GASTOS DE ABOGADO
B41: =IF(B36="Registro de Garantías Mobiliarias","Contrato de Garantía Mobiliaria","Contrato Leasing") -> Contrato Leasing | C41: SI | E41: 1 | F41: 400
B42: Autentica contrato de cobranza | C42: NO | F42: 0
B43: =IF($B$41="Contrato Leasing","","Contrato de Reconocimiento de Deuda")
B44: =IF($B$41="Contrato Leasing","","Auténtica Mandato") | G44: =SUM(F41:F45) -> 400
B46: Vehiculo Comercial | F46: DESCUENTOS DE: | G46: =G28+G38+G44+G16 -> 6914.589
B47: Valor de Mercado
...

Sheet Detalle cliente vehiculo
B15: Solicitante: | C15: ='Detalle vehiculo'!C5 -> 0
B16: Vehiculo:
B17: Inversionista: | C17: ='Detalle vehiculo'!C9 -> 0
B19: Monto Solicitado | D19: ='Detalle vehiculo'!G11 -> 43000
B21: Deducciones
B22: Cuotas interes mensual (interes sobre saldo) | C22: ='Detalle vehiculo'!G16 -> 0
B23: Royalty | C23: ='Detalle vehiculo'!F20 -> 1720
B24: Gastos Administrativos, Traspaso y Multa | C24: ='Detalle vehiculo'!F21+'Detalle vehiculo'!F27+'Detalle vehiculo'!G38 -> 2730
A25: * | B25: Cuotas de seguro (12 cuotas anuales)
A26: * | B26: Cuotas de GPS (mensual)
B27: Gastos legales | C27: ='Detalle vehiculo'!G44 -> 400 | D27: =SUM(C22:C27) -> 4850
B28: Líquido a recibir | D28: =D19-D27 -> 38150
B30: *La prima del seguro son 12 cuotas anuales que se pagan mensualmente, al momento de cancelar el credito se cancela el seguro.
B31: *El GPS se paga mensualmente, se cancela al momento de desinstalar el dispositivo GPS.
B33: Nota: El pago de GPS y Seguro son obligatorios y no estan incuidos dentro de la cuota mensual de interes.

Sheet Detalle hipotecario
C4: DETALLE DE GASTOS DE PRÉSTAMO OTORGADO
G11: 43790
B14: Nombre del Propietario: | C14: =#REF! -> #REF!
B15: Nombre del Solicitante del crédito: | C15: Mario Oswaldo Rosales Pur
B16: Dirección del Inmueble: | C16: =#REF! -> #REF!
B17: Datos del inmueble: | C17: Finca 139, folio 139, libro 2538 de Guatemala
C18: Inversionista:
A20: ► | B20: MONTO SOLICITADO EN QUETZALES: | G20: =C21*E21 -> 300000.01
B21: Tipo de cambio: US$ 1.00 x Q. | C21: 7.7 | E21: 38961.04
E22: % | F22: IVA
B23: Tasa de Interés: | C23: 0.03 | D23: Inversionista | E23: =G20*1.5/100 -> 4500.0001 | F23: =(E23)*12/100 -> 540.00001
A24: ► | B24: MES INTERES ANTICIPADO | C24: 1 | D24: Empresa Club C | E24: =G20*0.5/100 -> 1500 | F24: =(E24)*12/100 -> 180 | G24: =G20*C23*C24 -> 9000.0002
C25: IVA | F25: =(E25)*12/100 -> 0 | G25: =G24*12/100 -> 1080
D26: =D23 -> Inversionista | E26: =E23+F23 -> 5040.0001 | G26: =SUM(G24:G25) -> 10080
D27: =D24 -> Empresa Club C | E27: =SUM(E24:F24) -> 1680
D28: =D25 -> 0 | E28: =(E25)+(F25) -> 0
A29: ► | B29: COMISION Y GASTOS DE REGISTRO
B31: Royalty | E31: 0.04 | F31: =G20*E31 -> 12000 | G31: =SUM(F31:F36) -> 16591.25
B32: Otros Gastos | E32: 0.01 | F32: =G20*E32 -> 3000.0001
B33: IUSI | F33: 0
B34: Gastos administrativos | F34: 600
B35: Seguro | F35: 0
B36: Gastos de Registro (Registro Propiedad Inmueble) | F36: ='Cálculo RGPI'!C26 -> 991.25
B37: Otros Gastos
B39: GASTOS ESCRITURACION Y REGISTRO
B40: Memorial para registro temporal e inscripción RGPI | F40: 0
B41: Otros descuentos | F41: 0
G42: =SUM(F40:F41) -> 0
A44: ► | B44: GASTOS DE ABOGADO | G44: =SUM(F45:F50) -> 4060.0001
B45: Honorarios Escrituración | E45: 0.01 | F45: =(G20)*(E45)+(100) -> 3100.0001
B46: IVA | E46: =G16*0.3/100 -> 0 | F46: =(G20)*1/100*12/100 -> 360.00001
B47: Impuesto (base x millar) | C47: 2 | D47: o/oo | E47: 0 | F47: =G20*0.2/100 -> 600.00002
B48: Contrato de cobro | E48: 0 | F48: 0
B49: Liberación del inmueble | E49: 0 | F49: 0
B50: Carta de Pago | E50: 0 | F50: 0
B51: CALCULOS PAGO IMPUESTO DE OPERACIÓN
D52: x | E52: 0
D53: x | E53: 0
B54: Pago de Timbres
B55: Pago a efectuar de Hipoteca a nombre de:
...

Sheet Detalle cliente hipotecario
E11: 43790
A13: Solicitante:
A14: Mario Oswaldo Rosales Pur
A16: Préstamo otorgado | C16: ='Detalle hipotecario'!G20 -> 300000.01
A18: Deducciones
A19: 3% mensual 1a.cuota (incluye IVA) | B19: ='Detalle hipotecario'!G26 -> 10080
A20: Royalty 4% | B20: ='Detalle hipotecario'!F31 -> 12000
A21: Gastos Administrativos | B21: ='Detalle hipotecario'!F32+'Detalle hipotecario'!F34 -> 3600.0001
A22: Inscripciones (1o. Y 2do. Lugar, RGPI) | B22: ='Detalle hipotecario'!F36 -> 991.25
A23: Honorarios abogado | B23: ='Detalle hipotecario'!G44 -> 4060.0001 | C23: =SUM(B19:B23) -> 30731.251
A24: Líquido a recibir | C24: =C16-C23 -> 269268.76

Sheet Cálculo RGPI
A3: Base de cálculo Gastos de Registro
A4: 250000 | B4: - Q 10,0000 | C4: =A4-10000 -> 240000 | D4: =+A4/7.89 -> 31685.678
A6: =C4 -> 240000 | B6: x .015% | C6: =+A6*0.15/100 -> 360
A7: (+) Gastos
A8: Inscripción Registro | C8: =160+50 -> 210
A9: Scanner documento | C9: 75
A10: Gastos extraordinarios | C10: 0
C11: =+C10+C9+C8+C6 -> 645
A15: Base de cálculo Gastos de Registro
A16: 50000 | B16: - Q 10,0000 | C16: =A16-10000 -> 40000 | D16: =+A16/7.89 -> 6337.1356
A18: =C16 -> 40000 | B18: x .015% | C18: =+A18*0.15/100 -> 60
A19: (+) Gastos
A20: Inscripción Registro | C20: =160+50 -> 210
A21: Scanner documento | C21: 75
A22: Gastos extraordinarios | C22: 0
C23: =+C22+C21+C20+C18 -> 345
C26: =+C23+C11+(1.25) -> 991.25

Sheet Emision de Cheques
F8: MONEDA | G8: MONTO
A9: FECHA | B9: EMISOR | C9: BANCO | D9: BENEFICIARIO | E9: CONCEPTO | F9: Q | G9: Q
G10: ='Detalle vehiculo'!G48 -> 36085.411
G11: ='Detalle vehiculo'!G46 -> 6914.589
G14: =SUM(G10:G13) -> 43000
A20: © CLUB CASH IN . Este documento es propiedad de Club Cash In, copia u otro uso de este documento por y para terceras personas está prohibida.

Sheet Cotizador cliente
C10: Nombre:
C11: Valor del vehículo | K11: 89000
C12: Monto asegurado | K12: 45000
C13: Utilizacion del vehículo | K13: Particular
C14: Monto solicitado | K14: 43000
C15: Tasa de interés | K15: 0.03 | N15: =(K15*1.12) -> 0.0336
C16: Plazo (Meses) | K16: 60
C17: Seguro | K17: =(IF(K13="UBER",VLOOKUP(K12,'Costo de seguro'!B2:L782,2,TRUE),IF(K13="Particular",VLOOKUP(K12,'Costo de seguro'!B2:L782,2,TRUE),IF(K13="Pick Up",VLOOKUP(K12,'Costo de seguro'!B2:L782,3,TRUE),IF(K13="Nuevo",VLOOKUP(K12,'Costo de seguro'!B2:L207,2,TRUE),IF(K13="Panel",VLOOKUP(K12,'Costo de seguro'!B2:L782,4,TRUE),IF(K13="Camion",VLOOKUP(K12,'Costo de seguro'!B2:L207,4,TRUE),IF(K13="Microbus",VLOOKUP(K12,'Costo de seguro'!B2:L782,4,TRUE),""))))))))+K20 -> 471.589
C18: GPS | K18: 148.2
C19: Cuota (Sin servicios) | K19: =IFERROR(PMT(N15,K16,-K14),0) -> 1675.4672
C20: Membresía | K20: =VLOOKUP(K12,'Costo de seguro'!B2:P782,5,TRUE)-K18 -> 226.589
C21: Cuota mensual | K21: =K19+K18+K17 -> 2295.2562
A22: Cuota | B22: Mes | C22: Fecha de pago | D22: Saldo inicial | G22: Intereses | I22: IVA | K22: Interés + IVA | M22: Cuota | P22: Amortización | S22: Seguro | T22: GPS | U22: Saldo final | X22: Cuota mensual
A26: 1 | C26: 46021 | D26: =K14 -> 43000 | G26: =D26*$K$15 -> 1290 | I26: =G26*0.12 -> 154.8 | K26: =G26+I26 -> 1444.8 | M26: =$K$19 -> 1675.4672 | P26: =M26-K26 -> 230.66723 | S26: =IF(D26="","",$K$17) -> 471.589 | T26: =IF(D26="","",$K$18) -> 148.2 | U26: =D26-P26 -> 42769.333 | X26: =IFERROR(M26+S26+T26,"") -> 2295.2562
A27: =IF(C27="","",A26+1) -> 2 | B27: 1 | C27: =IF(D27="","",EDATE($C$26,B27)) -> 46052 | D27: =IF(D26="","",U26) -> 42769.333 | G27: =D27*$K$15 -> 1283.08 | I27: =G27*0.12 -> 153.9696 | K27: =G27+I27 -> 1437.0496 | M27: =$K$19 -> 1675.4672 | P27: =M27-K27 -> 238.41765 | S27: =IF(D27="","",$K$17) -> 471.589 | T27: =IF(D27="","",$K$18) -> 148.2 | U27: =D27-P27 -> 42530.915 | X27: =IF(D27="","",$X$26) -> 2295.2562
A28: =IF(C28="","",A27+1) -> 3 | B28: 2 | C28: =IF(D28="","",EDATE($C$26,B28)) -> 46081 | D28: =IF(D27="","",U27) -> 42530.915 | G28: =D28*$K$15 -> 1275.9275 | I28: =G28*0.12 -> 153.11129 | K28: =G28+I28 -> 1429.0387 | M28: =$K$19 -> 1675.4672 | P28: =M28-K28 -> 246.42848 | S28: =IF(D28="","",$K$17) -> 471.589 | T28: =IF(D28="","",$K$18) -> 148.2 | U28: =D28-P28 -> 42284.487 | X28: =IF(D28="","",$X$26) -> 2295.2562
A29: =IF(C29="","",A28+1) -> 4 | B29: 3 | C29: =IF(D29="","",EDATE($C$26,B29)) -> 46111 | D29: =IF(D28="","",U28) -> 42284.487 | G29: =D29*$K$15 -> 1268.5346 | I29: =G29*0.12 -> 152.22415 | K29: =G29+I29 -> 1420.7588 | M29: =$K$19 -> 1675.4672 | P29: =M29-K29 -> 254.70848 | S29: =IF(D29="","",$K$17) -> 471.589 | T29: =IF(D29="","",$K$18) -> 148.2 | U29: =D29-P29 -> 42029.778 | X29: =IF(D29="","",$X$26) -> 2295.2562
A30: =IF(C30="","",A29+1) -> 5 | B30: 4 | C30: =IF(D30="","",EDATE($C$26,B30)) -> 46142 | D30: =IF(D29="","",U29) -> 42029.778 | G30: =D30*$K$15 -> 1260.8933 | I30: =G30*0.12 -> 151.3072 | K30: =G30+I30 -> 1412.2005 | M30: =$K$19 -> 1675.4672 | P30: =M30-K30 -> 263.26668 | S30: =IF(D30="","",$K$17) -> 471.589 | T30: =IF(D30="","",$K$18) -> 148.2 | U30: =D30-P30 -> 41766.511 | X30: =IF(D30="","",$X$26) -> 2295.2562
A31: =IF(C31="","",A30+1) -> 6 | B31: 5 | C31: =IF(D31="","",EDATE($C$26,B31)) -> 46172 | D31: =IF(D30="","",U30) -> 41766.511 | G31: =D31*$K$15 -> 1252.9953 | I31: =G31*0.12 -> 150.35944 | K31: =IF(G31="","",G31+I31) -> 1403.3548 | M31: =$K$19 -> 1675.4672 | P31: =M31-K31 -> 272.11244 | S31: =IF(D31="","",$K$17) -> 471.589 | T31: =IF(D31="","",$K$18) -> 148.2 | U31: =D31-P31 -> 41494.399 | X31: =IF(D31="","",$X$26) -> 2295.2562
A32: =IF(C32="","",A31+1) -> 7 | B32: 6 | C32: =IF(D32="","",EDATE($C$26,B32)) -> 46203 | D32: =IF(U31<=0.1,"",U31) -> 41494.399 | G32: =IF(D32="","",(D32*$K$15)) -> 1244.832 | I32: =IF(G32="","",(G32*0.12)) -> 149.37984 | K32: =IF(G32="","",G32+I32) -> 1394.2118 | M32: =IF(D32="","",$K$19) -> 1675.4672 | P32: =IF(D32="","",M32-K32) -> 281.25542 | S32: =IF(D32="","",$K$17) -> 471.589 | T32: =IF(D32="","",$K$18) -> 148.2 | U32: =IF(D32="","",D32-P32) -> 41213.144 | X32: =IF(D32="","",$X$26) -> 2295.2562
A33: =IF(C33="","",A32+1) -> 8 | B33: 7 | C33: =IF(D33="","",EDATE($C$26,B33)) -> 46233 | D33: =IF(U32<=0.1,"",U32) -> 41213.144 | G33: =IF(D33="","",(D33*$K$15)) -> 1236.3943 | I33: =IF(G33="","",(G33*0.12)) -> 148.36732 | K33: =IF(G33="","",G33+I33) -> 1384.7616 | M33: =IF(I33="","",$K$19) -> 1675.4672 | P33: =IF(D33="","",M33-K33) -> 290.7056 | S33: =IF(D33="","",$K$17) -> 471.589 | T33: =IF(D33="","",$K$18) -> 148.2 | U33: =IF(D33="","",D33-P33) -> 40922.438 | X33: =IF(D33="","",$X$26) -> 2295.2562
A34: =IF(C34="","",A33+1) -> 9 | B34: 8 | C34: =IF(D34="","",EDATE($C$26,B34)) -> 46264 | D34: =IF(U33<=0.1,"",U33) -> 40922.438 | G34: =IF(D34="","",(D34*$K$15)) -> 1227.6731 | I34: =IF(G34="","",(G34*0.12)) -> 147.32078 | K34: =IF(G34="","",G34+I34) -> 1374.9939 | M34: =IF(I34="","",$K$19) -> 1675.4672 | P34: =IF(D34="","",M34-K34) -> 300.47331 | S34: =IF(D34="","",$K$17) -> 471.589 | T34: =IF(D34="","",$K$18) -> 148.2 | U34: =IF(D34="","",D34-P34) -> 40621.965 | X34: =IF(D34="","",$X$26) -> 2295.2562
A35: =IF(C35="","",A34+1) -> 10 | B35: 9 | C35: =IF(D35="","",EDATE($C$26,B35)) -> 46295 | D35: =IF(U34<=0.1,"",U34) -> 40621.965 | G35: =IF(D35="","",(D35*$K$15)) -> 1218.6589 | I35: =IF(G35="","",(G35*0.12)) -> 146.23907 | K35: =IF(G35="","",G35+I35) -> 1364.898 | M35: =IF(I35="","",$K$19) -> 1675.4672 | P35: =IF(D35="","",M35-K35) -> 310.56922 | S35: =IF(D35="","",$K$17) -> 471.589 | T35: =IF(D35="","",$K$18) -> 148.2 | U35: =IF(D35="","",D35-P35) -> 40311.395 | X35: =IF(D35="","",$X$26) -> 2295.2562
A36: =IF(C36="","",A35+1) -> 11 | B36: 10 | C36: =IF(D36="","",EDATE($C$26,B36)) -> 46325 | D36: =IF(U35<=0.1,"",U35) -> 40311.395 | G36: =IF(D36="","",(D36*$K$15)) -> 1209.3419 | I36: =IF(G36="","",(G36*0.12)) -> 145.12102 | K36: =IF(G36="","",G36+I36) -> 1354.4629 | M36: =IF(I36="","",$K$19) -> 1675.4672 | P36: =IF(D36="","",M36-K36) -> 321.00434 | S36: =IF(D36="","",$K$17) -> 471.589 | T36: =IF(D36="","",$K$18) -> 148.2 | U36: =IF(D36="","",D36-P36) -> 39990.391 | X36: =IF(D36="","",$X$26) -> 2295.2562
A37: =IF(C37="","",A36+1) -> 12 | B37: 11 | C37: =IF(D37="","",EDATE($C$26,B37)) -> 46356 | D37: =IF(U36<=0.1,"",U36) -> 39990.391 | G37: =IF(D37="","",(D37*$K$15)) -> 1199.7117 | I37: =IF(G37="","",(G37*0.12)) -> 143.96541 | K37: =IF(G37="","",G37+I37) -> 1343.6771 | M37: =IF(I37="","",$K$19) -> 1675.4672 | P37: =IF(D37="","",M37-K37) -> 331.79009 | S37: =IF(D37="","",$K$17) -> 471.589 | T37: =IF(D37="","",$K$18) -> 148.2 | U37: =IF(D37="","",D37-P37) -> 39658.601 | X37: =IF(D37="","",$X$26) -> 2295.2562
A38: =IF(C38="","",A37+1) -> 13 | B38: 12 | C38: =IF(D38="","",EDATE($C$26,B38)) -> 46386 | D38: =IF(U37<=0.1,"",U37) -> 39658.601 | G38: =IF(D38="","",(D38*$K$15)) -> 1189.758 | I38: =IF(G38="","",(G38*0.12)) -> 142.77096 | K38: =IF(G38="","",G38+I38) -> 1332.529 | M38: =IF(I38="","",$K$19) -> 1675.4672 | P38: =IF(D38="","",M38-K38) -> 342.93823 | S38: =IF(D38="","",$K$17) -> 471.589 | T38: =IF(D38="","",$K$18) -> 148.2 | U38: =IF(D38="","",D38-P38) -> 39315.663 | X38: =IF(D38="","",$X$26) -> 2295.2562
A39: =IF(C39="","",A38+1) -> 14 | B39: 13 | C39: =IF(D39="","",EDATE($C$26,B39)) -> 46417 | D39: =IF(U38<=0.1,"",U38) -> 39315.663 | G39: =IF(D39="","",(D39*$K$15)) -> 1179.4699 | I39: =IF(G39="","",(G39*0.12)) -> 141.53639 | K39: =IF(G39="","",G39+I39) -> 1321.0063 | M39: =IF(I39="","",$K$19) -> 1675.4672 | P39: =IF(D39="","",M39-K39) -> 354.46096 | S39: =IF(D39="","",$K$17) -> 471.589 | T39: =IF(D39="","",$K$18) -> 148.2 | U39: =IF(D39="","",D39-P39) -> 38961.202 | X39: =IF(D39="","",$X$26) -> 2295.2562
A40: =IF(C40="","",A39+1) -> 15 | B40: 14 | C40: =IF(D40="","",EDATE($C$26,B40)) -> 46446 | D40: =IF(U39<=0.1,"",U39) -> 38961.202 | G40: =IF(D40="","",(D40*$K$15)) -> 1168.8361 | I40: =IF(G40="","",(G40*0.12)) -> 140.26033 | K40: =IF(G40="","",G40+I40) -> 1309.0964 | M40: =IF(I40="","",$K$19) -> 1675.4672 | P40: =IF(D40="","",M40-K40) -> 366.37085 | S40: =IF(D40="","",$K$17) -> 471.589 | T40: =IF(D40="","",$K$18) -> 148.2 | U40: =IF(D40="","",D40-P40) -> 38594.831 | X40: =IF(D40="","",$X$26) -> 2295.2562
A41: =IF(C41="","",A40+1) -> 16 | B41: 15 | C41: =IF(D41="","",EDATE($C$26,B41)) -> 46476 | D41: =IF(U40<=0.1,"",U40) -> 38594.831 | G41: =IF(D41="","",(D41*$K$15)) -> 1157.8449 | I41: =IF(G41="","",(G41*0.12)) -> 138.94139 | K41: =IF(G41="","",G41+I41) -> 1296.7863 | M41: =IF(I41="","",$K$19) -> 1675.4672 | P41: =IF(D41="","",M41-K41) -> 378.68091 | S41: =IF(D41="","",$K$17) -> 471.589 | T41: =IF(D41="","",$K$18) -> 148.2 | U41: =IF(D41="","",D41-P41) -> 38216.15 | X41: =IF(D41="","",$X$26) -> 2295.2562
A42: =IF(C42="","",A41+1) -> 17 | B42: 16 | C42: =IF(D42="","",EDATE($C$26,B42)) -> 46507 | D42: =IF(U41<=0.1,"",U41) -> 38216.15 | G42: =IF(D42="","",(D42*$K$15)) -> 1146.4845 | I42: =IF(G42="","",(G42*0.12)) -> 137.57814 | K42: =IF(G42="","",G42+I42) -> 1284.0626 | M42: =IF(I42="","",$K$19) -> 1675.4672 | P42: =IF(D42="","",M42-K42) -> 391.40459 | S42: =IF(D42="","",$K$17) -> 471.589 | T42: =IF(D42="","",$K$18) -> 148.2 | U42: =IF(D42="","",D42-P42) -> 37824.746 | X42: =IF(D42="","",$X$26) -> 2295.2562
A43: =IF(C43="","",A42+1) -> 18 | B43: 17 | C43: =IF(D43="","",EDATE($C$26,B43)) -> 46537 | D43: =IF(U42<=0.1,"",U42) -> 37824.746 | G43: =IF(D43="","",(D43*$K$15)) -> 1134.7424 | I43: =IF(G43="","",(G43*0.12)) -> 136.16908 | K43: =IF(G43="","",G43+I43) -> 1270.9114 | M43: =IF(I43="","",$K$19) -> 1675.4672 | P43: =IF(D43="","",M43-K43) -> 404.55578 | S43: =IF(D43="","",$K$17) -> 471.589 | T43: =IF(D43="","",$K$18) -> 148.2 | U43: =IF(D43="","",D43-P43) -> 37420.19 | X43: =IF(D43="","",$X$26) -> 2295.2562
A44: =IF(C44="","",A43+1) -> 19 | B44: 18 | C44: =IF(D44="","",EDATE($C$26,B44)) -> 46568 | D44: =IF(U43<=0.1,"",U43) -> 37420.19 | G44: =IF(D44="","",(D44*$K$15)) -> 1122.6057 | I44: =IF(G44="","",(G44*0.12)) -> 134.71268 | K44: =IF(G44="","",G44+I44) -> 1257.3184 | M44: =IF(I44="","",$K$19) -> 1675.4672 | P44: =IF(D44="","",M44-K44) -> 418.14885 | S44: =IF(D44="","",$K$17) -> 471.589 | T44: =IF(D44="","",$K$18) -> 148.2 | U44: =IF(D44="","",D44-P44) -> 37002.041 | X44: =IF(D44="","",$X$26) -> 2295.2562
... A89: =IF(C89="","",A88+1) | B89: 63 | C89: =IF(D89="","",EDATE($C$26,B89)) | D89: =IF(U88<=0.1,"",U88) | G89: =IF(D89="","",(D89*$K$15)) | I89: =IF(G89="","",(G89*0.12)) | K89: =IF(G89="","",G89+I89) | M89: =IF(I89="","",$K$19) | P89: =IF(D89="","",M89-K89) | S89: =IF(D89="","",$K$17) | T89: =IF(D89="","",$K$18) | U89: =IF(D89="","",D89-P89) | X89: =IF(D89="","",$X$26)

Sheet Hoja3

Sheet Cotizador interno
C10: Nombre: | E10: ='Cotizador cliente'!E10:P10 -> 0
C11: Valor del vehículo | K11: ='Cotizador cliente'!K11 -> 89000
C12: Monto asegurado | K12: ='Cotizador cliente'!K12 -> 45000
C13: Utilizacion del vehículo | K13: ='Cotizador cliente'!K13 -> Particular
C14: Monto solicitado | K14: ='Cotizador cliente'!K14:M14 -> 43000
C15: Tasa de interés | K15: ='Cotizador cliente'!K15:M15 -> 0.03 | N15: =(K15*1.12) -> 0.0336
C16: Plazo (Meses) | K16: ='Cotizador cliente'!K16:M16 -> 60
C17: Seguro | K17: =(IF(K13="UBER",VLOOKUP(K12,'Costo de seguro'!B2:L782,2,TRUE),IF(K13="Particular",VLOOKUP(K12,'Costo de seguro'!B2:L782,2,TRUE),IF(K13="Pick Up",VLOOKUP(K12,'Costo de seguro'!B2:L782,3,TRUE),IF(K13="Nuevo",VLOOKUP(K12,'Costo de seguro'!B2:L782,2,TRUE),IF(K13="Panel",VLOOKUP(K12,'Costo de seguro'!B2:L782,4,TRUE),IF(K13="Camion",VLOOKUP(K12,'Costo de seguro'!B2:L782,4,TRUE),IF(K13="Microbus",VLOOKUP(K12,'Costo de seguro'!B2:L782,4,TRUE),"")))))))) -> 245
C18: Cuota (Sin servicios) | K18: =IFERROR(PMT(N15,K16,-K14),0) -> 1675.4672
C19: Membresía | K19: =VLOOKUP(K12,'Costo de seguro'!B2:P782,5,TRUE) -> 374.789
C20: Cuota mensual | K20: =K18+K17+K19 -> 2295.2562
A21: Cuota | B21: Mes | C21: Fecha de pago | D21: Saldo inicial | G21: Intereses | I21: IVA | K21: Interés + IVA | M21: Cuota | P21: Amortización | S21: Seguro | T21: Saldo final | W21: Cuota mensual
A25: 1 | C25: ='Cotizador cliente'!C26 -> 46021 | D25: =K14 -> 43000 | G25: =D25*$K$15 -> 1290 | I25: =G25*0.12 -> 154.8 | K25: =G25+I25 -> 1444.8 | M25: =$K$18 -> 1675.4672 | P25: =M25-K25 -> 230.66723 | S25: =IF(D25="","",$K$17) -> 245 | T25: =D25-P25 -> 42769.333 | W25: =IFERROR(M25+S25+$K$19,"") -> 2295.2562
A26: =IF(C26="","",A25+1) -> 2 | B26: 1 | C26: =IF(D26="","",EDATE($C$25,B26)) -> 46052 | D26: =IF(D25="","",T25) -> 42769.333 | G26: =D26*$K$15 -> 1283.08 | I26: =G26*0.12 -> 153.9696 | K26: =G26+I26 -> 1437.0496 | M26: =$K$18 -> 1675.4672 | P26: =M26-K26 -> 238.41765 | S26: =IF(D26="","",$K$17) -> 245 | T26: =D26-P26 -> 42530.915 | W26: =IF(D26="","",$W$25) -> 2295.2562
A27: =IF(C27="","",A26+1) -> 3 | B27: 2 | C27: =IF(D27="","",EDATE($C$25,B27)) -> 46081 | D27: =IF(D26="","",T26) -> 42530.915 | G27: =D27*$K$15 -> 1275.9275 | I27: =G27*0.12 -> 153.11129 | K27: =G27+I27 -> 1429.0387 | M27: =$K$18 -> 1675.4672 | P27: =M27-K27 -> 246.42848 | S27: =IF(D27="","",$K$17) -> 245 | T27: =D27-P27 -> 42284.487 | W27: =IF(D27="","",$W$25) -> 2295.2562
A28: =IF(C28="","",A27+1) -> 4 | B28: 3 | C28: =IF(D28="","",EDATE($C$25,B28)) -> 46111 | D28: =IF(D27="","",T27) -> 42284.487 | G28: =D28*$K$15 -> 1268.5346 | I28: =G28*0.12 -> 152.22415 | K28: =G28+I28 -> 1420.7588 | M28: =$K$18 -> 1675.4672 | P28: =M28-K28 -> 254.70848 | S28: =IF(D28="","",$K$17) -> 245 | T28: =D28-P28 -> 42029.778 | W28: =IF(D28="","",$W$25) -> 2295.2562
A29: =IF(C29="","",A28+1) -> 5 | B29: 4 | C29: =IF(D29="","",EDATE($C$25,B29)) -> 46142 | D29: =IF(D28="","",T28) -> 42029.778 | G29: =D29*$K$15 -> 1260.8933 | I29: =G29*0.12 -> 151.3072 | K29: =G29+I29 -> 1412.2005 | M29: =$K$18 -> 1675.4672 | P29: =M29-K29 -> 263.26668 | S29: =IF(D29="","",$K$17) -> 245 | T29: =D29-P29 -> 41766.511 | W29: =IF(D29="","",$W$25) -> 2295.2562
A30: =IF(C30="","",A29+1) -> 6 | B30: 5 | C30: =IF(D30="","",EDATE($C$25,B30)) -> 46172 | D30: =IF(D29="","",T29) -> 41766.511 | G30: =D30*$K$15 -> 1252.9953 | I30: =G30*0.12 -> 150.35944 | K30: =IF(G30="","",G30+I30) -> 1403.3548 | M30: =$K$18 -> 1675.4672 | P30: =M30-K30 -> 272.11244 | S30: =IF(D30="","",$K$17) -> 245 | T30: =D30-P30 -> 41494.399 | W30: =IF(D30="","",$W$25) -> 2295.2562
A31: =IF(C31="","",A30+1) -> 7 | B31: 6 | C31: =IF(D31="","",EDATE($C$25,B31)) -> 46203 | D31: =IF(T30<=0.1,"",T30) -> 41494.399 | G31: =IF(D31="","",(D31*$K$15)) -> 1244.832 | I31: =IF(G31="","",(G31*0.12)) -> 149.37984 | K31: =IF(G31="","",G31+I31) -> 1394.2118 | M31: =IF(D31="","",$K$18) -> 1675.4672 | P31: =IF(D31="","",M31-K31) -> 281.25542 | S31: =IF(D31="","",$K$17) -> 245 | T31: =IF(D31="","",D31-P31) -> 41213.144 | W31: =IF(D31="","",$W$25) -> 2295.2562
A32: =IF(C32="","",A31+1) -> 8 | B32: 7 | C32: =IF(D32="","",EDATE($C$25,B32)) -> 46233 | D32: =IF(T31<=0.1,"",T31) -> 41213.144 | G32: =IF(D32="","",(D32*$K$15)) -> 1236.3943 | I32: =IF(G32="","",(G32*0.12)) -> 148.36732 | K32: =IF(G32="","",G32+I32) -> 1384.7616 | M32: =IF(I32="","",$K$18) -> 1675.4672 | P32: =IF(D32="","",M32-K32) -> 290.7056 | S32: =IF(D32="","",$K$17) -> 245 | T32: =IF(D32="","",D32-P32) -> 40922.438 | W32: =IF(D32="","",$W$25) -> 2295.2562
A33: =IF(C33="","",A32+1) -> 9 | B33: 8 | C33: =IF(D33="","",EDATE($C$25,B33)) -> 46264 | D33: =IF(T32<=0.1,"",T32) -> 40922.438 | G33: =IF(D33="","",(D33*$K$15)) -> 1227.6731 | I33: =IF(G33="","",(G33*0.12)) -> 147.32078 | K33: =IF(G33="","",G33+I33) -> 1374.9939 | M33: =IF(I33="","",$K$18) -> 1675.4672 | P33: =IF(D33="","",M33-K33) -> 300.47331 | S33: =IF(D33="","",$K$17) -> 245 | T33: =IF(D33="","",D33-P33) -> 40621.965 | W33: =IF(D33="","",$W$25) -> 2295.2562
A34: =IF(C34="","",A33+1) -> 10 | B34: 9 | C34: =IF(D34="","",EDATE($C$25,B34)) -> 46295 | D34: =IF(T33<=0.1,"",T33) -> 40621.965 | G34: =IF(D34="","",(D34*$K$15)) -> 1218.6589 | I34: =IF(G34="","",(G34*0.12)) -> 146.23907 | K34: =IF(G34="","",G34+I34) -> 1364.898 | M34: =IF(I34="","",$K$18) -> 1675.4672 | P34: =IF(D34="","",M34-K34) -> 310.56922 | S34: =IF(D34="","",$K$17) -> 245 | T34: =IF(D34="","",D34-P34) -> 40311.395 | W34: =IF(D34="","",$W$25) -> 2295.2562
A35: =IF(C35="","",A34+1) -> 11 | B35: 10 | C35: =IF(D35="","",EDATE($C$25,B35)) -> 46325 | D35: =IF(T34<=0.1,"",T34) -> 40311.395 | G35: =IF(D35="","",(D35*$K$15)) -> 1209.3419 | I35: =IF(G35="","",(G35*0.12)) -> 145.12102 | K35: =IF(G35="","",G35+I35) -> 1354.4629 | M35: =IF(I35="","",$K$18) -> 1675.4672 | P35: =IF(D35="","",M35-K35) -> 321.00434 | S35: =IF(D35="","",$K$17) -> 245 | T35: =IF(D35="","",D35-P35) -> 39990.391 | W35: =IF(D35="","",$W$25) -> 2295.2562
A36: =IF(C36="","",A35+1) -> 12 | B36: 11 | C36: =IF(D36="","",EDATE($C$25,B36)) -> 46356 | D36: =IF(T35<=0.1,"",T35) -> 39990.391 | G36: =IF(D36="","",(D36*$K$15)) -> 1199.7117 | I36: =IF(G36="","",(G36*0.12)) -> 143.96541 | K36: =IF(G36="","",G36+I36) -> 1343.6771 | M36: =IF(I36="","",$K$18) -> 1675.4672 | P36: =IF(D36="","",M36-K36) -> 331.79009 | S36: =IF(D36="","",$K$17) -> 245 | T36: =IF(D36="","",D36-P36) -> 39658.601 | W36: =IF(D36="","",$W$25) -> 2295.2562
A37: =IF(C37="","",A36+1) -> 13 | B37: 12 | C37: =IF(D37="","",EDATE($C$25,B37)) -> 46386 | D37: =IF(T36<=0.1,"",T36) -> 39658.601 | G37: =IF(D37="","",(D37*$K$15)) -> 1189.758 | I37: =IF(G37="","",(G37*0.12)) -> 142.77096 | K37: =IF(G37="","",G37+I37) -> 1332.529 | M37: =IF(I37="","",$K$18) -> 1675.4672 | P37: =IF(D37="","",M37-K37) -> 342.93823 | S37: =IF(D37="","",$K$17) -> 245 | T37: =IF(D37="","",D37-P37) -> 39315.663 | W37: =IF(D37="","",$W$25) -> 2295.2562
A38: =IF(C38="","",A37+1) -> 14 | B38: 13 | C38: =IF(D38="","",EDATE($C$25,B38)) -> 46417 | D38: =IF(T37<=0.1,"",T37) -> 39315.663 | G38: =IF(D38="","",(D38*$K$15)) -> 1179.4699 | I38: =IF(G38="","",(G38*0.12)) -> 141.53639 | K38: =IF(G38="","",G38+I38) -> 1321.0063 | M38: =IF(I38="","",$K$18) -> 1675.4672 | P38: =IF(D38="","",M38-K38) -> 354.46096 | S38: =IF(D38="","",$K$17) -> 245 | T38: =IF(D38="","",D38-P38) -> 38961.202 | W38: =IF(D38="","",$W$25) -> 2295.2562
A39: =IF(C39="","",A38+1) -> 15 | B39: 14 | C39: =IF(D39="","",EDATE($C$25,B39)) -> 46446 | D39: =IF(T38<=0.1,"",T38) -> 38961.202 | G39: =IF(D39="","",(D39*$K$15)) -> 1168.8361 | I39: =IF(G39="","",(G39*0.12)) -> 140.26033 | K39: =IF(G39="","",G39+I39) -> 1309.0964 | M39: =IF(I39="","",$K$18) -> 1675.4672 | P39: =IF(D39="","",M39-K39) -> 366.37085 | S39: =IF(D39="","",$K$17) -> 245 | T39: =IF(D39="","",D39-P39) -> 38594.831 | W39: =IF(D39="","",$W$25) -> 2295.2562
A40: =IF(C40="","",A39+1) -> 16 | B40: 15 | C40: =IF(D40="","",EDATE($C$25,B40)) -> 46476 | D40: =IF(T39<=0.1,"",T39) -> 38594.831 | G40: =IF(D40="","",(D40*$K$15)) -> 1157.8449 | I40: =IF(G40="","",(G40*0.12)) -> 138.94139 | K40: =IF(G40="","",G40+I40) -> 1296.7863 | M40: =IF(I40="","",$K$18) -> 1675.4672 | P40: =IF(D40="","",M40-K40) -> 378.68091 | S40: =IF(D40="","",$K$17) -> 245 | T40: =IF(D40="","",D40-P40) -> 38216.15 | W40: =IF(D40="","",$W$25) -> 2295.2562
A41: =IF(C41="","",A40+1) -> 17 | B41: 16 | C41: =IF(D41="","",EDATE($C$25,B41)) -> 46507 | D41: =IF(T40<=0.1,"",T40) -> 38216.15 | G41: =IF(D41="","",(D41*$K$15)) -> 1146.4845 | I41: =IF(G41="","",(G41*0.12)) -> 137.57814 | K41: =IF(G41="","",G41+I41) -> 1284.0626 | M41: =IF(I41="","",$K$18) -> 1675.4672 | P41: =IF(D41="","",M41-K41) -> 391.40459 | S41: =IF(D41="","",$K$17) -> 245 | T41: =IF(D41="","",D41-P41) -> 37824.746 | W41: =IF(D41="","",$W$25) -> 2295.2562
A42: =IF(C42="","",A41+1) -> 18 | B42: 17 | C42: =IF(D42="","",EDATE($C$25,B42)) -> 46537 | D42: =IF(T41<=0.1,"",T41) -> 37824.746 | G42: =IF(D42="","",(D42*$K$15)) -> 1134.7424 | I42: =IF(G42="","",(G42*0.12)) -> 136.16908 | K42: =IF(G42="","",G42+I42) -> 1270.9114 | M42: =IF(I42="","",$K$18) -> 1675.4672 | P42: =IF(D42="","",M42-K42) -> 404.55578 | S42: =IF(D42="","",$K$17) -> 245 | T42: =IF(D42="","",D42-P42) -> 37420.19 | W42: =IF(D42="","",$W$25) -> 2295.2562
A43: =IF(C43="","",A42+1) -> 19 | B43: 18 | C43: =IF(D43="","",EDATE($C$25,B43)) -> 46568 | D43: =IF(T42<=0.1,"",T42) -> 37420.19 | G43: =IF(D43="","",(D43*$K$15)) -> 1122.6057 | I43: =IF(G43="","",(G43*0.12)) -> 134.71268 | K43: =IF(G43="","",G43+I43) -> 1257.3184 | M43: =IF(I43="","",$K$18) -> 1675.4672 | P43: =IF(D43="","",M43-K43) -> 418.14885 | S43: =IF(D43="","",$K$17) -> 245 | T43: =IF(D43="","",D43-P43) -> 37002.041 | W43: =IF(D43="","",$W$25) -> 2295.2562
... A88: =IF(C88="","",A87+1) | B88: 63 | C88: =IF(D88="","",EDATE($C$25,B88)) | D88: =IF(T87<=0.1,"",T87) | G88: =IF(D88="","",(D88*$K$15)) | I88: =IF(G88="","",(G88*0.12)) | K88: =IF(G88="","",G88+I88) | M88: =IF(I88="","",$K$18) | P88: =IF(D88="","",M88-K88) | S88: =IF(D88="","",$K$17) | T88: =IF(D88="","",D88-P88) | W88: =IF(D88="","",$W$25)

Sheet Costo de seguro
B1: Precio | C1: INREXSA | D1: Pick Up | E1: Panel, Camion, Microbus | F1: Membresia
B2: 20000 | C2: 245 | D2: 245 | E2: 245 | F2: 329.365
B3: 21000 | C3: 245 | D3: 245 | E3: 245 | F3: 329.365
B4: 22000 | C4: 245 | D4: 245 | E4: 245 | F4: 329.365
B5: 23000 | C5: 245 | D5: 245 | E5: 245 | F5: 329.365
B6: 24000 | C6: 245 | D6: 245 | E6: 245 | F6: 329.365
B7: 25000 | C7: 245 | D7: 245 | E7: 245 | F7: 329.365
B8: 26000 | C8: 245 | D8: 245 | E8: 245 | F8: 329.365
B9: 27000 | C9: 245 | D9: 245 | E9: 245 | F9: 329.365
B10: 28000 | C10: 245 | D10: 245 | E10: 245 | F10: 329.365
B11: 29000 | C11: 245 | D11: 245 | E11: 245 | F11: 329.365
B12: 30000 | C12: 245 | D12: 245 | E12: 245 | F12: 329.365
B13: 31000 | C13: 245 | D13: 245 | E13: 245 | F13: 329.365
... B782: 800000 | C782: 2156 | D782: 2399.04 | E782: 4704 | F782: 2339.7931

Sheet Detalle Cuota especial
C7: Capital | E7: 40000
C8: Tasa de interés | E8: 0.05 | L8: =(E8*1.12) -> 0.056 | AA8: Utilidad Neta Inversor
C9: Plazo (Meses) | E9: 36 | AB9: =SUM(AD18:AD52) -> 45570
C10: Cuota mensual (sin servicios) | E10: =G18+I18+E11+E12 -> 2904.57
C11: Seguro | E11: 516.37
C12: GPS | E12: 148.2
C13: Cuota mensual | E13: =SUM(E10:G12) -> 3569.14
C14: Inversionista | E14: 0.7
C15: Cash-in | E15: 0.3
AB16: Con impuestos | AD16: Sin impuestos
A17: No. Cuota | B17: Mes | C17: Fecha de pago | D17: Saldo inicial | G17: Intereses | I17: IVA | K17: Interés + IVA | M17: Cuota | P17: Amortización | S17: Seguro | T17: GPS | U17: Saldo final | X17: Cuota mensual | AA17: ISR | AB17: Inversionista | AC17: Cash-In | AD17: Inversionista | AE17: Cash-in
A18: 1 | C18: 43940 | D18: =E7 -> 40000 | G18: =D18*$E$8 -> 2000 | I18: =G18*0.12 -> 240 | K18: =G18+I18 -> 2240 | M18: =G18+I18+$E$11+$E$12 -> 2904.57 | S18: =IF(D18="","",$E$11) -> 516.37 | T18: =IF(D18="","",$E$12) -> 148.2 | U18: =D18-P18 -> 40000 | X18: =IFERROR(M18+S18+T18,"") -> 3569.14 | AA18: =G18*0.07 -> 140 | AB18: =(G18+I18)*$E$14 -> 1568 | AC18: =(G18+I18)*$E$15 -> 672 | AD18: =(G18-AA18)*$E$14 -> 1302 | AE18: =(G18-AA18)*$E$15 -> 558
A19: =IF(D19="","",B19+1) -> 2 | B19: 1 | C19: =IF(D19="","",EDATE(C18,B19)) -> 43970 | D19: =IF(U18<=0.1,"",U18) -> 40000 | G19: =IF(D19="","",(D19*$E$8)) -> 2000 | I19: =IF(G19="","",(G19*0.12)) -> 240 | K19: =IF(G19="","",G19+I19) -> 2240 | M19: =IF(I19="","",G19+I19+$E$11+$E$12) -> 2904.57 | P19: 0 | S19: =IF(D19="","",$E$11) -> 516.37 | T19: =IF(D19="","",$E$12) -> 148.2 | U19: =IF(P19="","",D19-P19) -> 40000 | X19: =IF(D19="","",$X$18) -> 3569.14 | AA19: =IF(G19="","",(G19*0.07)) -> 140 | AB19: =IF(G19="","",(G19+I19)*$E$14) -> 1568 | AC19: =IF(G19="","",(G19+I19)*$E$15) -> 672 | AD19: =IF(G19="","",(G19-AA19)*$E$14) -> 1302 | AE19: =IF(G19="","",(G19-AA19)*$E$15) -> 558
A20: =IF(D20="","",B20+1) -> 3 | B20: 2 | C20: =IF(D20="","",EDATE(C19,B20)) -> 44031 | D20: =IF(U19<=0.1,"",U19) -> 40000 | G20: =IF(D20="","",(D20*$E$8)) -> 2000 | I20: =IF(G20="","",(G20*0.12)) -> 240 | K20: =IF(G20="","",G20+I20) -> 2240 | M20: =IF(I20="","",G20+I20+$E$11+$E$12) -> 2904.57 | P20: 0 | S20: =IF(D20="","",$E$11) -> 516.37 | T20: =IF(D20="","",$E$12) -> 148.2 | U20: =IF(P20="","",D20-P20) -> 40000 | X20: =IF(D20="","",$X$18) -> 3569.14 | AA20: =IF(G20="","",(G20*0.07)) -> 140 | AB20: =IF(G20="","",(G20+I20)*$E$14) -> 1568 | AC20: =IF(G20="","",(G20+I20)*$E$15) -> 672 | AD20: =IF(G20="","",(G20-AA20)*$E$14) -> 1302 | AE20: =IF(G20="","",(G20-AA20)*$E$15) -> 558
A21: =IF(D21="","",B21+1) -> 4 | B21: 3 | C21: =IF(D21="","",EDATE(C20,B21)) -> 44123 | D21: =IF(U20<=0.1,"",U20) -> 40000 | G21: =IF(D21="","",(D21*$E$8)) -> 2000 | I21: =IF(G21="","",(G21*0.12)) -> 240 | K21: =IF(G21="","",G21+I21) -> 2240 | M21: =IF(I21="","",G21+I21+$E$11+$E$12) -> 2904.57 | P21: 0 | S21: =IF(D21="","",$E$11) -> 516.37 | T21: =IF(D21="","",$E$12) -> 148.2 | U21: =IF(P21="","",D21-P21) -> 40000 | X21: =IF(D21="","",$X$18) -> 3569.14 | AA21: =IF(G21="","",(G21*0.07)) -> 140 | AB21: =IF(G21="","",(G21+I21)*$E$14) -> 1568 | AC21: =IF(G21="","",(G21+I21)*$E$15) -> 672 | AD21: =IF(G21="","",(G21-AA21)*$E$14) -> 1302 | AE21: =IF(G21="","",(G21-AA21)*$E$15) -> 558
A22: =IF(D22="","",B22+1) -> 5 | B22: 4 | C22: =IF(D22="","",EDATE(C21,B22)) -> 44246 | D22: =IF(U21<=0.1,"",U21) -> 40000 | G22: =IF(D22="","",(D22*$E$8)) -> 2000 | I22: =IF(G22="","",(G22*0.12)) -> 240 | K22: =IF(G22="","",G22+I22) -> 2240 | M22: =IF(I22="","",G22+I22+$E$11+$E$12) -> 2904.57 | P22: 0 | S22: =IF(P22="","",$E$11) -> 516.37 | T22: =IF(P22="","",$E$12) -> 148.2 | U22: =IF(P22="","",D22-P22) -> 40000 | X22: =IF(P22="","",$X$18) -> 3569.14 | AA22: =IF(G22="","",(G22*0.07)) -> 140 | AB22: =IF(G22="","",(G22+I22)*$E$14) -> 1568 | AC22: =IF(G22="","",(G22+I22)*$E$15) -> 672 | AD22: =IF(G22="","",(G22-AA22)*$E$14) -> 1302 | AE22: =IF(G22="","",(G22-AA22)*$E$15) -> 558
A23: =IF(D23="","",B23+1) -> 6 | B23: 5 | C23: =IF(D23="","",EDATE(C22,B23)) -> 44396 | D23: =IF(U22<=0.1,"",U22) -> 40000 | G23: =IF(D23="","",(D23*$E$8)) -> 2000 | I23: =IF(G23="","",(G23*0.12)) -> 240 | K23: =IF(G23="","",G23+I23) -> 2240 | M23: =IF(I23="","",G23+I23+$E$11+$E$12) -> 2904.57 | P23: 0 | S23: =IF(P23="","",$E$11) -> 516.37 | T23: =IF(P23="","",$E$12) -> 148.2 | U23: =IF(P23="","",D23-P23) -> 40000 | X23: =IF(P23="","",$X$18) -> 3569.14 | AA23: =IF(G23="","",(G23*0.07)) -> 140 | AB23: =IF(G23="","",(G23+I23)*$E$14) -> 1568 | AC23: =IF(G23="","",(G23+I23)*$E$15) -> 672 | AD23: =IF(G23="","",(G23-AA23)*$E$14) -> 1302 | AE23: =IF(G23="","",(G23-AA23)*$E$15) -> 558
A24: =IF(D24="","",B24+1) -> 7 | B24: 6 | C24: =IF(D24="","",EDATE(C23,B24)) -> 44580 | D24: =IF(U23<=0.1,"",U23) -> 40000 | G24: =IF(D24="","",(D24*$E$8)) -> 2000 | I24: =IF(G24="","",(G24*0.12)) -> 240 | K24: =IF(G24="","",G24+I24) -> 2240 | M24: =IF(I24="","",G24+I24+$E$11+$E$12) -> 2904.57 | P24: 0 | S24: =IF(P24="","",$E$11) -> 516.37 | T24: =IF(P24="","",$E$12) -> 148.2 | U24: =IF(P24="","",D24-P24) -> 40000 | X24: =IF(P24="","",$X$18) -> 3569.14 | AA24: =IF(G24="","",(G24*0.07)) -> 140 | AB24: =IF(G24="","",(G24+I24)*$E$14) -> 1568 | AC24: =IF(G24="","",(G24+I24)*$E$15) -> 672 | AD24: =IF(G24="","",(G24-AA24)*$E$14) -> 1302 | AE24: =IF(G24="","",(G24-AA24)*$E$15) -> 558
A25: =IF(D25="","",B25+1) -> 8 | B25: 7 | C25: =IF(D25="","",EDATE(C24,B25)) -> 44792 | D25: =IF(U24<=0.1,"",U24) -> 40000 | G25: =IF(D25="","",(D25*$E$8)) -> 2000 | I25: =IF(G25="","",(G25*0.12)) -> 240 | K25: =IF(G25="","",G25+I25) -> 2240 | M25: =IF(I25="","",G25+I25+$E$11+$E$12) -> 2904.57 | P25: 0 | S25: =IF(P25="","",$E$11) -> 516.37 | T25: =IF(P25="","",$E$12) -> 148.2 | U25: =IF(P25="","",D25-P25) -> 40000 | X25: =IF(P25="","",$X$18) -> 3569.14 | AA25: =IF(G25="","",(G25*0.07)) -> 140 | AB25: =IF(G25="","",(G25+I25)*$E$14) -> 1568 | AC25: =IF(G25="","",(G25+I25)*$E$15) -> 672 | AD25: =IF(G25="","",(G25-AA25)*$E$14) -> 1302 | AE25: =IF(G25="","",(G25-AA25)*$E$15) -> 558
A26: =IF(D26="","",B26+1) -> 9 | B26: 8 | C26: =IF(D26="","",EDATE(C25,B26)) -> 45035 | D26: =IF(U25<=0.1,"",U25) -> 40000 | G26: =IF(D26="","",(D26*$E$8)) -> 2000 | I26: =IF(G26="","",(G26*0.12)) -> 240 | K26: =IF(G26="","",G26+I26) -> 2240 | M26: =IF(I26="","",G26+I26+$E$11+$E$12) -> 2904.57 | P26: 0 | S26: =IF(P26="","",$E$11) -> 516.37 | T26: =IF(P26="","",$E$12) -> 148.2 | U26: =IF(P26="","",D26-P26) -> 40000 | X26: =IF(P26="","",$X$18) -> 3569.14 | AA26: =IF(G26="","",(G26*0.07)) -> 140 | AB26: =IF(G26="","",(G26+I26)*$E$14) -> 1568 | AC26: =IF(G26="","",(G26+I26)*$E$15) -> 672 | AD26: =IF(G26="","",(G26-AA26)*$E$14) -> 1302 | AE26: =IF(G26="","",(G26-AA26)*$E$15) -> 558
A27: =IF(D27="","",B27+1) -> 10 | B27: 9 | C27: =IF(D27="","",EDATE(C26,B27)) -> 45310 | D27: =IF(U26<=0.1,"",U26) -> 40000 | G27: =IF(D27="","",(D27*$E$8)) -> 2000 | I27: =IF(G27="","",(G27*0.12)) -> 240 | K27: =IF(G27="","",G27+I27) -> 2240 | M27: =IF(I27="","",G27+I27+$E$11+$E$12) -> 2904.57 | P27: 0 | S27: =IF(P27="","",$E$11) -> 516.37 | T27: =IF(P27="","",$E$12) -> 148.2 | U27: =IF(P27="","",D27-P27) -> 40000 | X27: =IF(P27="","",$X$18) -> 3569.14 | AA27: =IF(G27="","",(G27*0.07)) -> 140 | AB27: =IF(G27="","",(G27+I27)*$E$14) -> 1568 | AC27: =IF(G27="","",(G27+I27)*$E$15) -> 672 | AD27: =IF(G27="","",(G27-AA27)*$E$14) -> 1302 | AE27: =IF(G27="","",(G27-AA27)*$E$15) -> 558
A28: =IF(D28="","",B28+1) -> 11 | B28: 10 | C28: =IF(D28="","",EDATE(C27,B28)) -> 45615 | D28: =IF(U27<=0.1,"",U27) -> 40000 | G28: =IF(D28="","",(D28*$E$8)) -> 2000 | I28: =IF(G28="","",(G28*0.12)) -> 240 | K28: =IF(G28="","",G28+I28) -> 2240 | M28: =IF(I28="","",G28+I28+$E$11+$E$12) -> 2904.57 | P28: 0 | S28: =IF(P28="","",$E$11) -> 516.37 | T28: =IF(P28="","",$E$12) -> 148.2 | U28: =IF(P28="","",D28-P28) -> 40000 | X28: =IF(P28="","",$X$18) -> 3569.14 | AA28: =IF(G28="","",(G28*0.07)) -> 140 | AB28: =IF(G28="","",(G28+I28)*$E$14) -> 1568 | AC28: =IF(G28="","",(G28+I28)*$E$15) -> 672 | AD28: =IF(G28="","",(G28-AA28)*$E$14) -> 1302 | AE28: =IF(G28="","",(G28-AA28)*$E$15) -> 558
A29: =IF(D29="","",B29+1) -> 12 | B29: 11 | C29: =IF(D29="","",EDATE(C28,B29)) -> 45949 | D29: =IF(U28<=0.1,"",U28) -> 40000 | G29: =IF(D29="","",(D29*$E$8)) -> 2000 | I29: =IF(G29="","",(G29*0.12)) -> 240 | K29: =IF(G29="","",G29+I29) -> 2240 | M29: =IF(I29="","",G29+I29+$E$11+$E$12) -> 2904.57 | P29: 0 | S29: =IF(P29="","",$E$11) -> 516.37 | T29: =IF(P29="","",$E$12) -> 148.2 | U29: =IF(P29="","",D29-P29) -> 40000 | X29: =IF(P29="","",$X$18) -> 3569.14 | AA29: =IF(G29="","",(G29*0.07)) -> 140 | AB29: =IF(G29="","",(G29+I29)*$E$14) -> 1568 | AC29: =IF(G29="","",(G29+I29)*$E$15) -> 672 | AD29: =IF(G29="","",(G29-AA29)*$E$14) -> 1302 | AE29: =IF(G29="","",(G29-AA29)*$E$15) -> 558
A30: =IF(D30="","",B30+1) -> 13 | B30: 12 | C30: =IF(D30="","",EDATE(C29,B30)) -> 46314 | D30: =IF(U29<=0.1,"",U29) -> 40000 | G30: =IF(D30="","",(D30*$E$8)) -> 2000 | I30: =IF(G30="","",(G30*0.12)) -> 240 | K30: =IF(G30="","",G30+I30) -> 2240 | M30: =IF(I30="","",G30+I30+$E$11+$E$12) -> 2904.57 | P30: 0 | S30: =IF(P30="","",$E$11) -> 516.37 | T30: =IF(P30="","",$E$12) -> 148.2 | U30: =IF(P30="","",D30-P30) -> 40000 | X30: =IF(P30="","",$X$18) -> 3569.14 | AA30: =IF(G30="","",(G30*0.07)) -> 140 | AB30: =IF(G30="","",(G30+I30)*$E$14) -> 1568 | AC30: =IF(G30="","",(G30+I30)*$E$15) -> 672 | AD30: =IF(G30="","",(G30-AA30)*$E$14) -> 1302 | AE30: =IF(G30="","",(G30-AA30)*$E$15) -> 558
A31: =IF(D31="","",B31+1) -> 14 | B31: 13 | C31: =IF(D31="","",EDATE(C30,B31)) -> 46710 | D31: =IF(U30<=0.1,"",U30) -> 40000 | G31: =IF(D31="","",(D31*$E$8)) -> 2000 | I31: =IF(G31="","",(G31*0.12)) -> 240 | K31: =IF(G31="","",G31+I31) -> 2240 | M31: =IF(I31="","",G31+I31+$E$11+$E$12) -> 2904.57 | P31: 0 | S31: =IF(P31="","",$E$11) -> 516.37 | T31: =IF(P31="","",$E$12) -> 148.2 | U31: =IF(P31="","",D31-P31) -> 40000 | X31: =IF(P31="","",$X$18) -> 3569.14 | AA31: =IF(G31="","",(G31*0.07)) -> 140 | AB31: =IF(G31="","",(G31+I31)*$E$14) -> 1568 | AC31: =IF(G31="","",(G31+I31)*$E$15) -> 672 | AD31: =IF(G31="","",(G31-AA31)*$E$14) -> 1302 | AE31: =IF(G31="","",(G31-AA31)*$E$15) -> 558
A32: =IF(D32="","",B32+1) -> 15 | B32: 14 | C32: =IF(D32="","",EDATE(C31,B32)) -> 47137 | D32: =IF(U31<=0.1,"",U31) -> 40000 | G32: =IF(D32="","",(D32*$E$8)) -> 2000 | I32: =IF(G32="","",(G32*0.12)) -> 240 | K32: =IF(G32="","",G32+I32) -> 2240 | M32: =IF(I32="","",G32+I32+$E$11+$E$12) -> 2904.57 | P32: 0 | S32: =IF(P32="","",$E$11) -> 516.37 | T32: =IF(P32="","",$E$12) -> 148.2 | U32: =IF(P32="","",D32-P32) -> 40000 | X32: =IF(P32="","",$X$18) -> 3569.14 | AA32: =IF(G32="","",(G32*0.07)) -> 140 | AB32: =IF(G32="","",(G32+I32)*$E$14) -> 1568 | AC32: =IF(G32="","",(G32+I32)*$E$15) -> 672 | AD32: =IF(G32="","",(G32-AA32)*$E$14) -> 1302 | AE32: =IF(G32="","",(G32-AA32)*$E$15) -> 558
A33: =IF(D33="","",B33+1) -> 16 | B33: 15 | C33: =IF(D33="","",EDATE(C32,B33)) -> 47592 | D33: =IF(U32<=0.1,"",U32) -> 40000 | G33: =IF(D33="","",(D33*$E$8)) -> 2000 | I33: =IF(G33="","",(G33*0.12)) -> 240 | K33: =IF(G33="","",G33+I33) -> 2240 | M33: =IF(I33="","",G33+I33+$E$11+$E$12) -> 2904.57 | P33: 0 | S33: =IF(P33="","",$E$11) -> 516.37 | T33: =IF(P33="","",$E$12) -> 148.2 | U33: =IF(P33="","",D33-P33) -> 40000 | X33: =IF(P33="","",$X$18) -> 3569.14 | AA33: =IF(G33="","",(G33*0.07)) -> 140 | AB33: =IF(G33="","",(G33+I33)*$E$14) -> 1568 | AC33: =IF(G33="","",(G33+I33)*$E$15) -> 672 | AD33: =IF(G33="","",(G33-AA33)*$E$14) -> 1302 | AE33: =IF(G33="","",(G33-AA33)*$E$15) -> 558
A34: =IF(D34="","",B34+1) -> 17 | B34: 16 | C34: =IF(D34="","",EDATE(C33,B34)) -> 48079 | D34: =IF(U33<=0.1,"",U33) -> 40000 | G34: =IF(D34="","",(D34*$E$8)) -> 2000 | I34: =IF(G34="","",(G34*0.12)) -> 240 | K34: =IF(G34="","",G34+I34) -> 2240 | M34: =IF(I34="","",G34+I34+$E$11+$E$12) -> 2904.57 | P34: 0 | S34: =IF(P34="","",$E$11) -> 516.37 | T34: =IF(P34="","",$E$12) -> 148.2 | U34: =IF(P34="","",D34-P34) -> 40000 | X34: =IF(P34="","",$X$18) -> 3569.14 | AA34: =IF(G34="","",(G34*0.07)) -> 140 | AB34: =IF(G34="","",(G34+I34)*$E$14) -> 1568 | AC34: =IF(G34="","",(G34+I34)*$E$15) -> 672 | AD34: =IF(G34="","",(G34-AA34)*$E$14) -> 1302 | AE34: =IF(G34="","",(G34-AA34)*$E$15) -> 558
A35: =IF(D35="","",B35+1) -> 18 | B35: 17 | C35: =IF(D35="","",EDATE(C34,B35)) -> 48598 | D35: =IF(U34<=0.1,"",U34) -> 40000 | G35: =IF(D35="","",(D35*$E$8)) -> 2000 | I35: =IF(G35="","",(G35*0.12)) -> 240 | K35: =IF(G35="","",G35+I35) -> 2240 | M35: =IF(I35="","",G35+I35+$E$11+$E$12) -> 2904.57 | P35: 0 | S35: =IF(D35="","",$E$11) -> 516.37 | T35: =IF(P35="","",$E$12) -> 148.2 | U35: =IF(P35="","",D35-P35) -> 40000 | X35: =IF(P35="","",$X$18) -> 3569.14 | AA35: =IF(G35="","",(G35*0.07)) -> 140 | AB35: =IF(G35="","",(G35+I35)*$E$14) -> 1568 | AC35: =IF(G35="","",(G35+I35)*$E$15) -> 672 | AD35: =IF(G35="","",(G35-AA35)*$E$14) -> 1302 | AE35: =IF(G35="","",(G35-AA35)*$E$15) -> 558
A36: =IF(D36="","",B36+1) -> 19 | B36: 18 | C36: =IF(D36="","",EDATE(C35,B36)) -> 49144 | D36: =IF(U35<=0.1,"",U35) -> 40000 | G36: =IF(D36="","",(D36*$E$8)) -> 2000 | I36: =IF(G36="","",(G36*0.12)) -> 240 | K36: =IF(G36="","",G36+I36) -> 2240 | M36: =IF(I36="","",G36+I36+$E$11+$E$12) -> 2904.57 | P36: 0 | S36: =IF(D36="","",$E$11) -> 516.37 | T36: =IF(D36="","",$E$12) -> 148.2 | U36: =IF(P36="","",D36-P36) -> 40000 | X36: =IF(D36="","",$X$18) -> 3569.14 | AA36: =IF(G36="","",(G36*0.07)) -> 140 | AB36: =IF(G36="","",(G36+I36)*$E$14) -> 1568 | AC36: =IF(G36="","",(G36+I36)*$E$15) -> 672 | AD36: =IF(G36="","",(G36-AA36)*$E$14) -> 1302 | AE36: =IF(G36="","",(G36-AA36)*$E$15) -> 558
A37: =IF(D37="","",B37+1) -> 20 | B37: 19 | C37: =IF(D37="","",EDATE(C36,B37)) -> 49724 | D37: =IF(U36<=0.1,"",U36) -> 40000 | G37: =IF(D37="","",(D37*$E$8)) -> 2000 | I37: =IF(G37="","",(G37*0.12)) -> 240 | K37: =IF(G37="","",G37+I37) -> 2240 | M37: =IF(I37="","",G37+I37+$E$11+$E$12) -> 2904.57 | P37: 0 | S37: =IF(D37="","",$E$11) -> 516.37 | T37: =IF(D37="","",$E$12) -> 148.2 | U37: =IF(P37="","",D37-P37) -> 40000 | X37: =IF(D37="","",$X$18) -> 3569.14 | AA37: =IF(G37="","",(G37*0.07)) -> 140 | AB37: =IF(G37="","",(G37+I37)*$E$14) -> 1568 | AC37: =IF(G37="","",(G37+I37)*$E$15) -> 672 | AD37: =IF(G37="","",(G37-AA37)*$E$14) -> 1302 | AE37: =IF(G37="","",(G37-AA37)*$E$15) -> 558
A38: =IF(D38="","",B38+1) -> 21 | B38: 20 | C38: =IF(D38="","",EDATE(C37,B38)) -> 50332 | D38: =IF(U37<=0.1,"",U37) -> 40000 | G38: =IF(D38="","",(D38*$E$8)) -> 2000 | I38: =IF(G38="","",(G38*0.12)) -> 240 | K38: =IF(G38="","",G38+I38) -> 2240 | M38: =IF(I38="","",G38+I38+$E$11+$E$12) -> 2904.57 | P38: 0 | S38: =IF(D38="","",$E$11) -> 516.37 | T38: =IF(D38="","",$E$12) -> 148.2 | U38: =IF(P38="","",D38-P38) -> 40000 | X38: =IF(D38="","",$X$18) -> 3569.14 | AA38: =IF(G38="","",(G38*0.07)) -> 140 | AB38: =IF(G38="","",(G38+I38)*$E$14) -> 1568 | AC38: =IF(G38="","",(G38+I38)*$E$15) -> 672 | AD38: =IF(G38="","",(G38-AA38)*$E$14) -> 1302 | AE38: =IF(G38="","",(G38-AA38)*$E$15) -> 558
A39: =IF(D39="","",B39+1) -> 22 | B39: 21 | C39: =IF(D39="","",EDATE(C38,B39)) -> 50970 | D39: =IF(U38<=0.1,"",U38) -> 40000 | G39: =IF(D39="","",(D39*$E$8)) -> 2000 | I39: =IF(G39="","",(G39*0.12)) -> 240 | K39: =IF(G39="","",G39+I39) -> 2240 | M39: =IF(I39="","",G39+I39+$E$11+$E$12) -> 2904.57 | P39: 0 | S39: =IF(D39="","",$E$11) -> 516.37 | T39: =IF(D39="","",$E$12) -> 148.2 | U39: =IF(P39="","",D39-P39) -> 40000 | X39: =IF(D39="","",$X$18) -> 3569.14 | AA39: =IF(G39="","",(G39*0.07)) -> 140 | AB39: =IF(G39="","",(G39+I39)*$E$14) -> 1568 | AC39: =IF(G39="","",(G39+I39)*$E$15) -> 672 | AD39: =IF(G39="","",(G39-AA39)*$E$14) -> 1302 | AE39: =IF(G39="","",(G39-AA39)*$E$15) -> 558
A40: =IF(D40="","",B40+1) -> 23 | B40: 22 | C40: =IF(D40="","",EDATE(C39,B40)) -> 51640 | D40: =IF(U39<=0.1,"",U39) -> 40000 | G40: =IF(D40="","",(D40*$E$8)) -> 2000 | I40: =IF(G40="","",(G40*0.12)) -> 240 | K40: =IF(G40="","",G40+I40) -> 2240 | M40: =IF(I40="","",G40+I40+$E$11+$E$12) -> 2904.57 | P40: 0 | S40: =IF(D40="","",$E$11) -> 516.37 | T40: =IF(D40="","",$E$12) -> 148.2 | U40: =IF(P40="","",D40-P40) -> 40000 | X40: =IF(D40="","",$X$18) -> 3569.14 | AA40: =IF(G40="","",(G40*0.07)) -> 140 | AB40: =IF(G40="","",(G40+I40)*$E$14) -> 1568 | AC40: =IF(G40="","",(G40+I40)*$E$15) -> 672 | AD40: =IF(G40="","",(G40-AA40)*$E$14) -> 1302 | AE40: =IF(G40="","",(G40-AA40)*$E$15) -> 558
A41: =IF(D41="","",B41+1) -> 24 | B41: 23 | C41: =IF(D41="","",EDATE(C40,B41)) -> 52340 | D41: =IF(U40<=0.1,"",U40) -> 40000 | G41: =IF(D41="","",(D41*$E$8)) -> 2000 | I41: =IF(G41="","",(G41*0.12)) -> 240 | K41: =IF(G41="","",G41+I41) -> 2240 | M41: =IF(I41="","",G41+I41+$E$11+$E$12) -> 2904.57 | P41: 0 | S41: =IF(D41="","",$E$11) -> 516.37 | T41: =IF(D41="","",$E$12) -> 148.2 | U41: =IF(P41="","",D41-P41) -> 40000 | X41: =IF(D41="","",$X$18) -> 3569.14 | AA41: =IF(G41="","",(G41*0.07)) -> 140 | AB41: =IF(G41="","",(G41+I41)*$E$14) -> 1568 | AC41: =IF(G41="","",(G41+I41)*$E$15) -> 672 | AD41: =IF(G41="","",(G41-AA41)*$E$14) -> 1302 | AE41: =IF(G41="","",(G41-AA41)*$E$15) -> 558
A42: =IF(D42="","",B42+1) -> 25 | B42: 24 | C42: =IF(D42="","",EDATE(C41,B42)) -> 53071 | D42: =IF(U41<=0.1,"",U41) -> 40000 | G42: =IF(D42="","",(D42*$E$8)) -> 2000 | I42: =IF(G42="","",(G42*0.12)) -> 240 | K42: =IF(G42="","",G42+I42) -> 2240 | M42: =IF(I42="","",G42+I42+$E$11+$E$12) -> 2904.57 | P42: 0 | S42: =IF(D42="","",$E$11) -> 516.37 | T42: =IF(D42="","",$E$12) -> 148.2 | U42: =IF(P42="","",D42-P42) -> 40000 | X42: =IF(D42="","",$X$18) -> 3569.14 | AA42: =IF(G42="","",(G42*0.07)) -> 140 | AB42: =IF(G42="","",(G42+I42)*$E$14) -> 1568 | AC42: =IF(G42="","",(G42+I42)*$E$15) -> 672 | AD42: =IF(G42="","",(G42-AA42)*$E$14) -> 1302 | AE42: =IF(G42="","",(G42-AA42)*$E$15) -> 558
A43: =IF(D43="","",B43+1) -> 26 | B43: 25 | C43: =IF(D43="","",EDATE(C42,B43)) -> 53831 | D43: =IF(U42<=0.1,"",U42) -> 40000 | G43: =IF(D43="","",(D43*$E$8)) -> 2000 | I43: =IF(G43="","",(G43*0.12)) -> 240 | K43: =IF(G43="","",G43+I43) -> 2240 | M43: =IF(I43="","",G43+I43+$E$11+$E$12) -> 2904.57 | P43: 0 | S43: =IF(D43="","",$E$11) -> 516.37 | T43: =IF(D43="","",$E$12) -> 148.2 | U43: =IF(P43="","",D43-P43) -> 40000 | X43: =IF(D43="","",$X$18) -> 3569.14 | AA43: =IF(G43="","",(G43*0.07)) -> 140 | AB43: =IF(G43="","",(G43+I43)*$E$14) -> 1568 | AC43: =IF(G43="","",(G43+I43)*$E$15) -> 672 | AD43: =IF(G43="","",(G43-AA43)*$E$14) -> 1302 | AE43: =IF(G43="","",(G43-AA43)*$E$15) -> 558
A44: =IF(D44="","",B44+1) -> 27 | B44: 26 | C44: =IF(D44="","",EDATE(C43,B44)) -> 54623 | D44: =IF(U43<=0.1,"",U43) -> 40000 | G44: =IF(D44="","",(D44*$E$8)) -> 2000 | I44: =IF(G44="","",(G44*0.12)) -> 240 | K44: =IF(G44="","",G44+I44) -> 2240 | M44: =IF(I44="","",G44+I44+$E$11+$E$12) -> 2904.57 | P44: 0 | S44: =IF(D44="","",$E$11) -> 516.37 | T44: =IF(D44="","",$E$12) -> 148.2 | U44: =IF(P44="","",D44-P44) -> 40000 | X44: =IF(D44="","",$X$18) -> 3569.14 | AA44: =IF(G44="","",(G44*0.07)) -> 140 | AB44: =IF(G44="","",(G44+I44)*$E$14) -> 1568 | AC44: =IF(G44="","",(G44+I44)*$E$15) -> 672 | AD44: =IF(G44="","",(G44-AA44)*$E$14) -> 1302 | AE44: =IF(G44="","",(G44-AA44)*$E$15) -> 558
A45: =IF(D45="","",B45+1) -> 28 | B45: 27 | C45: =IF(D45="","",EDATE(C44,B45)) -> 55445 | D45: =IF(U44<=0.1,"",U44) -> 40000 | G45: =IF(D45="","",(D45*$E$8)) -> 2000 | I45: =IF(G45="","",(G45*0.12)) -> 240 | K45: =IF(G45="","",G45+I45) -> 2240 | M45: =IF(I45="","",G45+I45+$E$11+$E$12) -> 2904.57 | P45: 0 | S45: =IF(D45="","",$E$11) -> 516.37 | T45: =IF(D45="","",$E$12) -> 148.2 | U45: =IF(P45="","",D45-P45) -> 40000 | X45: =IF(D45="","",$X$18) -> 3569.14 | AA45: =IF(G45="","",(G45*0.07)) -> 140 | AB45: =IF(G45="","",(G45+I45)*$E$14) -> 1568 | AC45: =IF(G45="","",(G45+I45)*$E$15) -> 672 | AD45: =IF(G45="","",(G45-AA45)*$E$14) -> 1302 | AE45: =IF(G45="","",(G45-AA45)*$E$15) -> 558
A46: =IF(D46="","",B46+1) -> 29 | B46: 28 | C46: =IF(D46="","",EDATE(C45,B46)) -> 56299 | D46: =IF(U45<=0.1,"",U45) -> 40000 | G46: =IF(D46="","",(D46*$E$8)) -> 2000 | I46: =IF(G46="","",(G46*0.12)) -> 240 | K46: =IF(G46="","",G46+I46) -> 2240 | M46: =IF(I46="","",G46+I46+$E$11+$E$12) -> 2904.57 | P46: 0 | S46: =IF(D46="","",$E$11) -> 516.37 | T46: =IF(D46="","",$E$12) -> 148.2 | U46: =IF(P46="","",D46-P46) -> 40000 | X46: =IF(D46="","",$X$18) -> 3569.14 | AA46: =IF(G46="","",(G46*0.07)) -> 140 | AB46: =IF(G46="","",(G46+I46)*$E$14) -> 1568 | AC46: =IF(G46="","",(G46+I46)*$E$15) -> 672 | AD46: =IF(G46="","",(G46-AA46)*$E$14) -> 1302 | AE46: =IF(G46="","",(G46-AA46)*$E$15) -> 558
...

Sheet Analisis de pago
B2: Tipo de credito | C2: =#REF! -> #REF!
B4: Edad | C4: =#REF! -> #REF! | D4: =IFERROR(VLOOKUP(C4,'Datos - analisis de pago'!B4:C7,2,FALSE),"0") -> 0 | E4: 1 | F4: 2
B5: Residencia | C5: =#REF! -> #REF! | D5: =IFERROR(VLOOKUP(C5,'Datos - analisis de pago'!E4:F20,2,FALSE),0) -> 0 | E5: 1 | F5: 2
B6: Coinciden direcciones? | C6: =#REF! -> #REF! | D6: =IFERROR(VLOOKUP(C6,'Datos - analisis de pago'!H5:I6,2,FALSE),0) -> 0 | E6: 1 | F6: 4 | G6: =SUM(F4:F6) -> 8 | I6: =IF(C2="Hipotecario",IF(D30=0,"",IF(D30<=30,"A",IF(D30<=50,"B",IF(D30<=70,"C",IF(D30<=340,"D",""))))),IF(D30=0,"",IF(D30<=30,"A",IF(D30<=50,"B",IF(D30<=70,"C",IF(D30<=340,"D","")))))) -> #REF!
B7: Estado civil | C7: =#REF! -> #REF! | D7: =IFERROR(VLOOKUP(C7,'Datos - analisis de pago'!B24:C26,2,FALSE),0) -> 0 | E7: 1 | F7: 4
B8: Tiene dependientes | C8: =#REF! -> #REF! | D8: =IFERROR(VLOOKUP(C8,'Datos - analisis de pago'!E24:F25,2,FALSE),0) -> 0 | E8: 1 | F8: 4
B9: Capacidad de endeudamiento | C9: =#REF! -> #REF! | D9: =IFERROR(VLOOKUP(C9,'Datos - analisis de pago'!H24:I30,2,FALSE),0) -> 0 | E9: 2 | F9: 4 | I9: =IF(I6="","","Tasa a Ofrecer") -> #REF!
B10: Dentro de sus egresos paga alguna deuda? | C10: =#REF! -> #REF! | D10: =IFERROR(VLOOKUP(C10,'Datos - analisis de pago'!O24:P25,2,FALSE),0) -> 0 | E10: 1 | F10: 4 | I10: =IF(I6="A","1% - 1.5%",IF(I6="B","1.6% - 2%",IF(I6="C","2.1% - 2.5%",IF(I6="D","3%","")))) -> #REF!
B11: Esta orgulloso de sus actividades? | C11: =#REF! -> #REF! | D11: =IFERROR(VLOOKUP(C11,'Datos - analisis de pago'!L24:M25,2,FALSE),0) -> 0 | E11: 1 | F11: 4 | G11: =SUM(F7:F11) -> 20
B12: Tiene cuenta bancaria | C12: =#REF! -> #REF! | D12: =IFERROR(VLOOKUP(C12,'Datos - analisis de pago'!B33:C34,2,FALSE),0) -> 0 | E12: 1 | F12: 3
B13: Tiene tarjeta de credito | C13: =#REF! -> #REF! | D13: =IFERROR(VLOOKUP(C13,'Datos - analisis de pago'!E33:F34,2,FALSE),0) -> 0 | E13: 0.5 | F13: 3
B14: La tiene al día? | C14: =#REF! -> #REF! | D14: =IFERROR(VLOOKUP(C14,'Datos - analisis de pago'!H33:I34,2,FALSE),0) -> 0 | E14: 0.5 | F14: 7
B15: Cuantos créditos activos tiene? | C15: =#REF! -> #REF! | D15: =IFERROR(VLOOKUP(C15,'Datos - analisis de pago'!N33:O38,2,FALSE),0) -> 0 | E15: 0 | F15: 2
B16: Capacidad de endeudamiento | C16: =#REF! -> #REF! | D16: =IF(C16<0,10,IFERROR(VLOOKUP(C16,'Datos - analisis de pago'!A51:C150,3,TRUE),0)) -> #REF! | E16: 0.5 | F16: 1
B17: Posee cuotas atrasadas? | C17: =#REF! -> #REF! | D17: =IFERROR(VLOOKUP(C17,'Datos - analisis de pago'!R33:S34,2,FALSE),0) -> 0 | E17: 0.5 | F17: 5
B18: Cantidad de cuotas atrasadas | C18: =#REF! -> #REF! | D18: =IFERROR(VLOOKUP(C18,'Datos - analisis de pago'!V33:W38,2,FALSE),0) -> 0 | E18: 0.5 | F18: 7
B19: Es honrado? | C19: =#REF! -> #REF! | D19: =IFERROR(VLOOKUP(C19,'Datos - analisis de pago'!K33:L34,2,FALSE),0) -> 0 | E19: 0.5 | F19: 7 | G19: =SUM(F12:F19) -> 35
B20: Tiene alguna deuda sobre la propiedad | C20: =#REF! -> #REF! | D20: =IFERROR(VLOOKUP(C20,'Datos - analisis de pago'!E40:F41,2,FALSE),0) -> 0 | E20: 0.5 | F20: 5
B21: Tiene IUSI al día? | C21: =#REF! -> #REF! | D21: =IFERROR(VLOOKUP(C21,'Datos - analisis de pago'!E45:F46,2,FALSE),0) -> 0 | E21: 1 | F21: 5
B22: Cuantos trimestres adeuda? | C22: =#REF! -> #REF! | D22: =IFERROR(VLOOKUP(C22,'Datos - analisis de pago'!H45:I48,2,FALSE),0) -> 0 | E22: 0.5 | F22: 5
B23: Que logro tener algo propio! | C23: =#REF! -> #REF! | D23: =IFERROR(VLOOKUP(C23,'Datos - analisis de pago'!H40:I41,2,FALSE),0) -> 0 | E23: 0.5 | F23: 5 | G23: =SUM(F20:F23) -> 20
B24: Cuota nivelada vs. Capacidad de endeudamiento | C24: =#REF! -> #REF! | D24: =IF(C24="",0,IF(C24>1,10,(IFERROR(VLOOKUP(C24,'Datos - analisis de pago'!A51:B150,2,TRUE),IF(C24<0,10,(IFERROR(VLOOKUP(C24,'Datos - analisis de pago'!A51:B150,2,TRUE),0))))))) -> #REF! | E24: 1 | F24: 2.5
B25: Garantia propia | C25: =#REF! -> #REF! | D25: =IFERROR(VLOOKUP(C25,'Datos - analisis de pago'!F51:G52,2,FALSE),0) -> 0 | E25: 1 | F25: 2.5 | G25: =SUM(F24:F25) -> 5
B26: Impuesto de circulacion del año en curso pagado? | C26: =#REF! -> #REF! | D26: =IFERROR(VLOOKUP(C26,'Datos - analisis de pago'!K45:L46,2,FALSE),0) -> 0 | E26: 0.5 | F26: 5
B27: Días en mora? | C27: =#REF! -> #REF! | D27: =IFERROR(VLOOKUP(C27,'Datos - analisis de pago'!P45:Q47,2,FALSE),0) -> 0 | E27: 0.5 | F27: 5
B28: Que logro tener algo propio! | C28: =#REF! -> #REF! | D28: =IFERROR(VLOOKUP(C28,'Datos - analisis de pago'!O40:P41,2,FALSE),0) -> 0 | E28: 0.5 | F28: 5 | G28: =SUM(F26:F28) -> 15
E29: =SUM(E4:E25) -> 17.5 | F29: =SUM(F4:F25) -> 88 | G29: =SUM(G5:G28) -> 103
D30: =IF(C2="Hipotecario",SUM(D4:D25),(SUM(D4:D19)+D24+D25+D26+D27+D28)) -> #REF!

Sheet Datos - analisis de pago
B3: Edad | E3: Municipio | L3: Cuotas
B4: 40 - 49 años | C4: 1 | E4: Guatemala | F4: 1 | H4: Coinciden direcciones | L4: Cuota nivelada
B5: 30 - 39 años | C5: 1 | E5: Santa Catarina Pinula | F5: 1.5 | H5: Si | I5: 1 | L5: Cuota de intereses
B6: 18 - 29 años | C6: 1.5 | E6: San José Pinula | F6: 1.5 | H6: No | I6: 4
B7: 70 años o mas | C7: 2 | E7: San José del Golfo | F7: 2
E8: Palencia | F8: 2
E9: Chinautla | F9: 2
E10: San Pedro Ayampuc | F10: 2
E11: Mixco | F11: 1
E12: San Pedro Sacatepéquez | F12: 1.5
E13: San Juan Sacatepéquez | F13: 1.5
E14: San Raymundo | F14: 1.5 | I14: Mejor | J14: Peor
E15: Chuarrancho | F15: 1.5 | I15: =(0.15*3)/0.15 -> 3 | J15: =(0.15*15)/0.15 -> 15
E16: Fraijanes | F16: 1
E17: Amatitlán | F17: 1.5
E18: Villa Nueva | F18: 1
E19: Villa Canales | F19: 1.5
E20: Petapa | F20: 1.5
B23: Estado civil | E23: Tiene dependientes | H23: capacidad de endeudamiento | L23: Esta orgulloso de sus actividades | O23: Dentro de sus egresos paga alguna deuda?
B24: Casado | C24: 1 | E24: Si | F24: 4 | H24: Q0 - Q1000 | I24: 10 | L24: Si | M24: 1 | O24: Si | P24: 4
B25: Soltero | C25: 4 | E25: No | F25: 1 | H25: Q1,001 - Q3,000 | I25: 4 | L25: No | M25: 4 | O25: No | P25: 1
B26: Viudo/a | C26: 3 | H26: Q3,001 - Q6,000 | I26: 3.5
H27: Q6,001 - Q10,000 | I27: 3
H28: Q10,001 - Q15,000 | I28: 2.5
H29: Q15,001 - Q25,000 | I29: 2.5
H30: Q25,001 en adelante | I30: 2
B32: Tiene cuenta en algun banco ? | E32: Tiene o ha tenido tarjeta de credito? | H32: La tiene al día? | K32: Es honrado? | N32: Cuantos créditos activos tiene? | R32: Posee cuotas atrasadas | V32: Cantidad de cuotas atrasadas
B33: Si | C33: 1 | E33: Si | F33: 0.5 | H33: Si | I33: 0.5 | K33: Si | L33: 0.5 | N33: 0 | O33: 0 | R33: Si | S33: 5 | V33: 0 | W33: 0
B34: No | C34: 3 | E34: No | F34: 3 | H34: No | I34: 7 | K34: No | L34: 7 | N34: 1 | O34: 0.5 | R34: No | S34: 0.5 | V34: 1 | W34: 0.5
N35: 2 | O35: 0.5 | V35: 2 | W35: 3
N36: 3 | O36: 1 | V36: 3 | W36: 4
N37: 4 | O37: 1.5 | V37: 4 | W37: 6
N38: 5+ | O38: 2 | V38: 5+ | W38: 7
B39: Tipo de propiedad | E39: Tiene alguna deuda sobre la propiedad | H39: Que logro tener algo propio! | L39: Origen | O39: Que logro tener algo propio!
B40: Terreno | C40: 0.5 | E40: Si | F40: 5 | H40: Si | I40: 0.5 | L40: Rodado | M40: 2 | O40: Si | P40: 0.5
B41: Lote | C41: 2 | E41: No | F41: 0.5 | H41: No | I41: 5 | L41: Agencia | M41: 0.5 | O41: No | P41: 5
B42: Casa | C42: 0.5
B43: Apartamento | C43: 0.5
B44: Bodega | C44: 3 | E44: Tiene IUSI al día? | H44: Cuantos trimestres adeuda? | K44: Impuesto de circulacion del año en curso pagado? | P44: Días en mora
B45: Edificio | C45: 5 | E45: Si | F45: 1 | H45: 1 | I45: 0.5 | K45: Si | L45: 0.5 | P45: 30 | Q45: 0.5
...

Sheet Datos - analisis garantia
A1: 1
A2: 2
A3: 3
A4: 4
A5: 5
A6: 6
A7: 7
A8: 8
A9: 9
A10: 10
A11: 11
A12: 12
A13: 13
A14: 14 | C14: informacion general | D14: =SUM(L17:L18) -> 88
A15: 15
A16: 16 | C16: Edad | F16: Zona | I16: medio en el que nos vio
A17: 17 | C17: 40 - 49 años | D17: 5 | F17: Casco Urbano | G17: 3 | I17: Facebook | L17: =SUM(D17:D20) -> 65 | N17: Pregunta #1
A18: 18 | C18: 30 - 39 años | D18: 5 | F18: Ciudad Satelite | G18: 5 | I18: Instagram | L18: =SUM(G17:G20) -> 23 | N18: Si | O18: 5
A19: 19 | C19: 18 - 29 años | D19: 20 | F19: Interior Casco | G19: 7 | I19: Volantes | N19: No | O19: 15
A20: 20 | C20: 70 años o mas | D20: 35 | F20: Interior Rural | G20: 8 | I20: Activacion
A21: 21 | I21: Prensa
A22: 22
A23: 23
A24: 24 | C24: informacion laboral | D24: =D27+D28+D29+F27+F28+F31+F32+I27+I28+I29+I30+I31+I32+L27+L28+L29+L30+O27+O28+O29+R27+R28+R29+R30+R31+R32+U27+U28+U29+U30+U31+U32+X27+X28+AA28+AA29+AA30+AA31+AA32+AA33 -> 116
A25: 25
C26: Estado civil | E26: Tiene dependientes economicos? | H26: Cuantos dependientes? | K26: Ocupacion | N26: Inicio de labores | Q26: Ingresos | T26: Egresos | W26: Afiliacion al IGSS | Z26: capacidad de endeudamiento | AC26: cuota nivelada ideal | AE26: Pregunta #2
C27: Casado | D27: 1 | E27: Si | F27: 5 | H27: 0 | I27: 0 | K27: Empleado | L27: 3 | N27: 0-1 año | O27: 5 | Q27: Q1,000 - Q3,000 | R27: 5 | T27: Q1,000 - Q3,000 | U27: 1 | W27: Si | X27: 1 | Z27: Q0 - Q1000 | AA27: 8 | AE27: Si | AF27: 1
A28: 1960 | C28: Soltero | D28: 5 | E28: No | F28: 1 | H28: 1 | I28: 1 | K28: Dueño | L28: 1 | N28: 1-5 años | O28: 3 | Q28: Q3,001 - Q6,000 | R28: 4 | T28: Q3,001 - Q6,000 | U28: 2 | W28: No | X28: 5 | Z28: Q1,001 - Q3,000 | AA28: 5 | AE28: No | AF28: 5
A29: 1961 | C29: Viudo/a | D29: 3 | H29: 2 | I29: 2 | K29: Desempleado | L29: 5 | N29: 5-10 años | O29: 1 | Q29: Q6,001 - Q10,000 | R29: 3 | T29: Q6,001 - Q10,000 | U29: 3 | Z29: Q3,001 - Q6,000 | AA29: 4
A30: 1962 | E30: Tiene mascotas | H30: 3 | I30: 3 | K30: retirado | L30: 3 | Q30: Q10,001 - Q15,000 | R30: 2 | T30: Q10,001 - Q15,000 | U30: 4 | Z30: Q6,001 - Q10,000 | AA30: 3
A31: 1963 | E31: Si | F31: 5 | H31: 4 | I31: 4 | Q31: Q15,001 - Q25,000 | R31: 1 | T31: Q15,001 - Q25,000 | U31: 5 | Z31: Q10,001 - Q15,000 | AA31: 2
A32: 1964 | E32: No | F32: 1 | H32: 5+ | I32: 5 | Q32: Q25,001 en adelante | R32: 1 | T32: Q25,001 en adelante | U32: 6 | Z32: Q15,001 - Q25,000 | AA32: 1
A33: 1965 | Z33: Q25,001 en adelante | AA33: 1
A34: 1966
A35: 1967 | C35: Informacion crediticia
A36: 1968
A37: 1969 | C37: Tiene cuenta en algun banco ? | F37: Estados de cuenta | I37: Tiene o ha tenido tarjeta de credito? | L37: La tiene funcionando | O37: El dinero lo utilizara en ….? | S37: Ha tenido algun credito ? | V37: Vivienda propia ? | Y37: Vehiculo propio | AB37: Pregunta #3
A38: 1970 | C38: Si | D38: 2 | F38: Si | G38: 2 | I38: Si | J38: 2 | L38: Si | M38: 1 | O38: Capital de trabajo | P38: 3 | S38: hipotecario | V38: Si | W38: 2 | Y38: Si | Z38: 2 | AB38: Si | AC38: 1
A39: 1971 | C39: No | D39: 10 | F39: No | G39: 10 | I39: No | J39: 10 | L39: No | M39: 10 | O39: Salud o Medico | P39: 15 | S39: vehiculo | V39: No | W39: 10 | Y39: No | Z39: 10 | AB39: No | AC39: 5
A40: 1972 | O40: Consumo | P40: 20 | S40: consumo
...

Sheet Analisis garantia
J2: CATALOGO DE RIESGO
B7: Nombre:
